ERROR 2018-12-04 08:49:44,668 exception 80 Invalid HTTP_HOST header: '127.0.0.1:8000'. You may need to add '127.0.0.1' to ALLOWED_HOSTS.
WARNING 2018-12-04 08:49:46,346 basehttp 124 "GET / HTTP/1.1" 400 70619
ERROR 2018-12-04 08:49:47,342 exception 80 Invalid HTTP_HOST header: '127.0.0.1:8000'. You may need to add '127.0.0.1' to ALLOWED_HOSTS.
WARNING 2018-12-04 08:49:47,735 basehttp 124 "GET /favicon.ico HTTP/1.1" 400 70672
INFO 2018-12-04 08:50:29,517 basehttp 124 "GET / HTTP/1.1" 200 1714
WARNING 2018-12-04 08:50:29,897 base 152 Not Found: /favicon.ico
WARNING 2018-12-04 08:50:29,904 basehttp 124 "GET /favicon.ico HTTP/1.1" 404 1966
WARNING 2018-12-04 10:05:50,039 base 152 Not Found: /
WARNING 2018-12-04 10:05:50,050 basehttp 124 "GET / HTTP/1.1" 404 2104
WARNING 2018-12-04 10:05:53,528 base 152 Not Found: /
WARNING 2018-12-04 10:05:53,542 basehttp 124 "GET / HTTP/1.1" 404 2104
WARNING 2018-12-04 10:05:55,286 base 152 Not Found: /
WARNING 2018-12-04 10:05:55,311 basehttp 124 "GET / HTTP/1.1" 404 2104
WARNING 2018-12-04 10:06:59,357 base 152 Not Found: /register.html
WARNING 2018-12-04 10:06:59,376 basehttp 124 "GET /register.html HTTP/1.1" 404 2161
WARNING 2018-12-04 10:08:50,164 base 152 Not Found: /
WARNING 2018-12-04 10:08:50,170 basehttp 124 "GET / HTTP/1.1" 404 2104
ERROR 2018-12-04 10:08:51,647 exception 80 Invalid HTTP_HOST header: '127.0.0.1:8000'. You may need to add '127.0.0.1' to ALLOWED_HOSTS.
WARNING 2018-12-04 10:08:52,482 basehttp 124 "GET / HTTP/1.1" 400 71076
ERROR 2018-12-04 10:08:53,339 exception 80 Invalid HTTP_HOST header: '127.0.0.1:8000'. You may need to add '127.0.0.1' to ALLOWED_HOSTS.
WARNING 2018-12-04 10:08:53,383 basehttp 124 "GET /favicon.ico HTTP/1.1" 400 71129
WARNING 2018-12-04 10:09:03,340 base 152 Not Found: /
WARNING 2018-12-04 10:09:03,350 basehttp 124 "GET / HTTP/1.1" 404 2104
WARNING 2018-12-04 10:09:06,742 base 152 Not Found: /
WARNING 2018-12-04 10:09:06,762 basehttp 124 "GET / HTTP/1.1" 404 2104
ERROR 2018-12-04 10:09:29,956 exception 80 Invalid HTTP_HOST header: 'www.meiduo.site:8000'. You may need to add 'www.meiduo.site' to ALLOWED_HOSTS.
WARNING 2018-12-04 10:09:30,051 basehttp 124 "GET / HTTP/1.1" 400 70134
ERROR 2018-12-04 10:09:30,383 exception 80 Invalid HTTP_HOST header: 'www.meiduo.site:8000'. You may need to add 'www.meiduo.site' to ALLOWED_HOSTS.
WARNING 2018-12-04 10:09:30,453 basehttp 124 "GET /favicon.ico HTTP/1.1" 400 70193
WARNING 2018-12-04 10:11:00,283 base 152 Not Found: /
WARNING 2018-12-04 10:11:00,304 basehttp 124 "GET / HTTP/1.1" 404 2104
WARNING 2018-12-04 10:11:00,450 base 152 Not Found: /favicon.ico
WARNING 2018-12-04 10:11:00,454 basehttp 124 "GET /favicon.ico HTTP/1.1" 404 2155
WARNING 2018-12-04 10:12:20,628 base 152 Not Found: /register.html
WARNING 2018-12-04 10:12:20,634 basehttp 124 "GET /register.html HTTP/1.1" 404 2161
WARNING 2018-12-04 10:19:41,722 base 152 Not Found: /
WARNING 2018-12-04 10:19:41,766 basehttp 124 "GET / HTTP/1.1" 404 2104
WARNING 2018-12-04 10:23:04,782 base 152 Not Found: /
WARNING 2018-12-04 10:23:04,795 basehttp 124 "GET / HTTP/1.1" 404 2104
WARNING 2018-12-04 10:23:08,556 base 152 Not Found: /
WARNING 2018-12-04 10:23:08,581 basehttp 124 "GET / HTTP/1.1" 404 2104
WARNING 2018-12-04 10:23:52,041 base 152 Not Found: /
WARNING 2018-12-04 10:23:52,075 basehttp 124 "GET / HTTP/1.1" 404 74
WARNING 2018-12-04 10:23:57,142 base 152 Not Found: /
WARNING 2018-12-04 10:23:57,164 basehttp 124 "GET / HTTP/1.1" 404 74
ERROR 2018-12-04 10:25:41,888 exception 80 Invalid HTTP_HOST header: '127.0.0.1:8000'. You may need to add '127.0.0.1' to ALLOWED_HOSTS.
WARNING 2018-12-04 10:25:42,418 basehttp 124 "GET / HTTP/1.1" 400 71076
ERROR 2018-12-04 10:25:43,197 exception 80 Invalid HTTP_HOST header: '127.0.0.1:8000'. You may need to add '127.0.0.1' to ALLOWED_HOSTS.
WARNING 2018-12-04 10:25:43,527 basehttp 124 "GET /favicon.ico HTTP/1.1" 400 71129
WARNING 2018-12-04 10:25:59,250 base 152 Not Found: /
WARNING 2018-12-04 10:25:59,274 basehttp 124 "GET / HTTP/1.1" 404 2104
WARNING 2018-12-04 10:25:59,370 base 152 Not Found: /favicon.ico
WARNING 2018-12-04 10:25:59,372 basehttp 124 "GET /favicon.ico HTTP/1.1" 404 2155
WARNING 2018-12-04 10:26:03,024 base 152 Not Found: /
WARNING 2018-12-04 10:26:03,040 basehttp 124 "GET / HTTP/1.1" 404 2104
WARNING 2018-12-04 10:34:16,155 base 152 Not Found: /mobiles/13112345678/count/
WARNING 2018-12-04 10:34:16,175 basehttp 124 "GET /mobiles/13112345678/count/ HTTP/1.1" 404 2200
WARNING 2018-12-04 10:34:16,204 base 152 Not Found: /mobiles/13112345678/count/
WARNING 2018-12-04 10:34:16,213 basehttp 124 "GET /mobiles/13112345678/count/ HTTP/1.1" 404 2200
INFO 2018-12-04 10:34:16,242 basehttp 124 "GET /sms_code/13112345678/ HTTP/1.1" 200 16
WARNING 2018-12-04 10:34:17,186 base 152 Not Found: /mobiles/13112345678/count/
INFO 2018-12-04 10:34:17,195 basehttp 124 "GET /sms_code/13112345678/ HTTP/1.1" 200 23
WARNING 2018-12-04 10:34:17,202 basehttp 124 "GET /mobiles/13112345678/count/ HTTP/1.1" 404 2200
WARNING 2018-12-04 10:34:18,882 base 152 Not Found: /mobiles/13112345678/count/
WARNING 2018-12-04 10:34:18,884 basehttp 124 "GET /mobiles/13112345678/count/ HTTP/1.1" 404 2200
WARNING 2018-12-04 10:34:19,368 base 152 Not Found: /mobiles/13112345678/count/
INFO 2018-12-04 10:34:19,376 basehttp 124 "GET /sms_code/13112345678/ HTTP/1.1" 200 23
WARNING 2018-12-04 10:34:19,381 basehttp 124 "GET /mobiles/13112345678/count/ HTTP/1.1" 404 2200
WARNING 2018-12-04 10:34:20,158 base 152 Not Found: /mobiles/13112345678/count/
INFO 2018-12-04 10:34:20,161 basehttp 124 "GET /sms_code/13112345678/ HTTP/1.1" 200 23
WARNING 2018-12-04 10:34:20,168 basehttp 124 "GET /mobiles/13112345678/count/ HTTP/1.1" 404 2200
WARNING 2018-12-04 10:34:20,328 base 152 Not Found: /mobiles/13112345678/count/
INFO 2018-12-04 10:34:20,333 basehttp 124 "GET /sms_code/13112345678/ HTTP/1.1" 200 23
WARNING 2018-12-04 10:34:20,336 basehttp 124 "GET /mobiles/13112345678/count/ HTTP/1.1" 404 2200
WARNING 2018-12-04 10:34:20,517 base 152 Not Found: /mobiles/13112345678/count/
INFO 2018-12-04 10:34:20,528 basehttp 124 "GET /sms_code/13112345678/ HTTP/1.1" 200 23
WARNING 2018-12-04 10:34:20,533 basehttp 124 "GET /mobiles/13112345678/count/ HTTP/1.1" 404 2200
WARNING 2018-12-04 10:34:58,740 base 152 Not Found: /
WARNING 2018-12-04 10:34:58,753 basehttp 124 "GET / HTTP/1.1" 404 2104
WARNING 2018-12-04 10:34:58,893 base 152 Not Found: /favicon.ico
WARNING 2018-12-04 10:34:58,902 basehttp 124 "GET /favicon.ico HTTP/1.1" 404 2155
WARNING 2018-12-04 10:36:16,967 base 152 Not Found: /
WARNING 2018-12-04 10:36:16,981 basehttp 124 "GET / HTTP/1.1" 404 2104
WARNING 2018-12-04 10:36:17,142 base 152 Not Found: /favicon.ico
WARNING 2018-12-04 10:36:17,149 basehttp 124 "GET /favicon.ico HTTP/1.1" 404 2155
WARNING 2018-12-04 10:37:23,843 base 152 Not Found: /mobiles/13112345678/count/
WARNING 2018-12-04 10:37:23,858 basehttp 124 "GET /mobiles/13112345678/count/ HTTP/1.1" 404 2200
INFO 2018-12-04 10:37:23,879 basehttp 124 "GET /sms_code/13112345678/ HTTP/1.1" 200 16
WARNING 2018-12-04 10:37:23,880 base 152 Not Found: /mobiles/13112345678/count/
WARNING 2018-12-04 10:37:23,882 basehttp 124 "GET /mobiles/13112345678/count/ HTTP/1.1" 404 2200
WARNING 2018-12-04 10:39:16,913 base 152 Not Found: /mobiles/13112345678/count/
INFO 2018-12-04 10:39:16,918 basehttp 124 "GET /sms_code/13112345678/ HTTP/1.1" 200 16
WARNING 2018-12-04 10:39:16,923 basehttp 124 "GET /mobiles/13112345678/count/ HTTP/1.1" 404 2200
WARNING 2018-12-04 11:20:11,267 base 152 Not Found: /mobiles/13112345678/count/
WARNING 2018-12-04 11:20:11,281 basehttp 124 "GET /mobiles/13112345678/count/ HTTP/1.1" 404 2200
WARNING 2018-12-04 11:20:11,492 base 152 Not Found: /mobiles/13112345678/count/
WARNING 2018-12-04 11:20:11,494 basehttp 124 "GET /mobiles/13112345678/count/ HTTP/1.1" 404 2200
WARNING 2018-12-04 11:20:15,726 base 152 Not Found: /mobiles/13112345678/count/
WARNING 2018-12-04 11:20:15,730 basehttp 124 "GET /mobiles/13112345678/count/ HTTP/1.1" 404 2200
INFO 2018-12-04 11:20:15,983 basehttp 124 "GET /sms_code/13112345678/ HTTP/1.1" 200 16
WARNING 2018-12-05 16:00:45,600 base 152 Not Found: /
WARNING 2018-12-05 16:00:45,624 basehttp 124 "GET / HTTP/1.1" 404 2299
WARNING 2018-12-05 16:00:46,708 base 152 Not Found: /favicon.ico
WARNING 2018-12-05 16:00:46,710 basehttp 124 "GET /favicon.ico HTTP/1.1" 404 2350
INFO 2018-12-05 16:06:44,155 basehttp 124 "GET /usernames/name123/count/ HTTP/1.1" 200 32
WARNING 2018-12-05 16:10:39,380 base 152 Not Found: /mobiles/13112345678/count/
WARNING 2018-12-05 16:10:39,386 basehttp 124 "GET /mobiles/13112345678/count/ HTTP/1.1" 404 2395
INFO 2018-12-05 16:16:07,604 basehttp 124 "GET /mobiles/13112345678/count/ HTTP/1.1" 200 34
INFO 2018-12-05 17:28:37,457 basehttp 124 "GET /usernames/python123/count/ HTTP/1.1" 200 34
INFO 2018-12-05 17:28:47,371 basehttp 124 "GET /mobiles/13112345678/count/ HTTP/1.1" 200 34
INFO 2018-12-05 17:28:47,421 basehttp 124 "GET /sms_code/13112345678/ HTTP/1.1" 200 16
INFO 2018-12-05 17:29:44,226 basehttp 124 "OPTIONS /users/ HTTP/1.1" 200 0
INFO 2018-12-05 17:29:44,333 basehttp 124 "GET /mobiles/13112345678/count/ HTTP/1.1" 200 34
INFO 2018-12-05 17:29:44,348 basehttp 124 "GET /usernames/python123/count/ HTTP/1.1" 200 34
INFO 2018-12-05 17:29:44,781 basehttp 124 "POST /users/ HTTP/1.1" 201 54
WARNING 2018-12-06 09:46:17,902 base 152 Not Found: /
WARNING 2018-12-06 09:46:17,937 basehttp 124 "GET / HTTP/1.1" 404 2649
WARNING 2018-12-06 09:46:18,166 base 152 Not Found: /favicon.ico
WARNING 2018-12-06 09:46:18,169 basehttp 124 "GET /favicon.ico HTTP/1.1" 404 2700
INFO 2018-12-07 09:23:44,743 basehttp 124 "OPTIONS /authorizations/ HTTP/1.1" 200 0
WARNING 2018-12-07 09:23:45,986 basehttp 124 "POST /authorizations/ HTTP/1.1" 400 38
WARNING 2018-12-07 09:24:18,949 basehttp 124 "POST /authorizations/ HTTP/1.1" 400 38
WARNING 2018-12-07 09:29:25,245 basehttp 124 "POST /authorizations/ HTTP/1.1" 400 38
WARNING 2018-12-07 09:29:25,949 basehttp 124 "POST /authorizations/ HTTP/1.1" 400 38
WARNING 2018-12-07 09:29:34,543 basehttp 124 "POST /authorizations/ HTTP/1.1" 400 38
ERROR 2018-12-07 09:29:52,922 exception 135 Internal Server Error: /authorizations/
Traceback (most recent call last):
  File "/home/python/.virtualenvs/py3_django/lib/python3.5/site-packages/rest_framework/views.py", line 480, in dispatch
    response = handler(request, *args, **kwargs)
  File "/home/python/.virtualenvs/py3_django/lib/python3.5/site-packages/rest_framework/views.py", line 157, in http_method_not_allowed
    raise exceptions.MethodNotAllowed(request.method)
rest_framework.exceptions.MethodNotAllowed: 方法 “GET” 不被允许。

During handling of the above exception, another exception occurred:

Traceback (most recent call last):
  File "/home/python/.virtualenvs/py3_django/lib/python3.5/site-packages/rest_framework/settings.py", line 183, in import_from_string
    module = import_module(module_path)
  File "/home/python/.virtualenvs/py3_django/lib/python3.5/importlib/__init__.py", line 126, in import_module
    return _bootstrap._gcd_import(name[level:], package, level)
  File "<frozen importlib._bootstrap>", line 986, in _gcd_import
  File "<frozen importlib._bootstrap>", line 969, in _find_and_load
  File "<frozen importlib._bootstrap>", line 944, in _find_and_load_unlocked
  File "<frozen importlib._bootstrap>", line 222, in _call_with_frames_removed
  File "<frozen importlib._bootstrap>", line 986, in _gcd_import
  File "<frozen importlib._bootstrap>", line 969, in _find_and_load
  File "<frozen importlib._bootstrap>", line 956, in _find_and_load_unlocked
ImportError: No module named 'utils'

During handling of the above exception, another exception occurred:

Traceback (most recent call last):
  File "/home/python/.virtualenvs/py3_django/lib/python3.5/site-packages/django/core/handlers/exception.py", line 41, in inner
    response = get_response(request)
  File "/home/python/.virtualenvs/py3_django/lib/python3.5/site-packages/django/core/handlers/base.py", line 187, in _get_response
    response = self.process_exception_by_middleware(e, request)
  File "/home/python/.virtualenvs/py3_django/lib/python3.5/site-packages/django/core/handlers/base.py", line 185, in _get_response
    response = wrapped_callback(request, *callback_args, **callback_kwargs)
  File "/home/python/.virtualenvs/py3_django/lib/python3.5/site-packages/django/views/decorators/csrf.py", line 58, in wrapped_view
    return view_func(*args, **kwargs)
  File "/home/python/.virtualenvs/py3_django/lib/python3.5/site-packages/django/views/generic/base.py", line 68, in view
    return self.dispatch(request, *args, **kwargs)
  File "/home/python/.virtualenvs/py3_django/lib/python3.5/site-packages/rest_framework/views.py", line 483, in dispatch
    response = self.handle_exception(exc)
  File "/home/python/.virtualenvs/py3_django/lib/python3.5/site-packages/rest_framework/views.py", line 437, in handle_exception
    exception_handler = self.get_exception_handler()
  File "/home/python/.virtualenvs/py3_django/lib/python3.5/site-packages/rest_framework/views.py", line 288, in get_exception_handler
    return self.settings.EXCEPTION_HANDLER
  File "/home/python/.virtualenvs/py3_django/lib/python3.5/site-packages/rest_framework/settings.py", line 227, in __getattr__
    val = perform_import(val, attr)
  File "/home/python/.virtualenvs/py3_django/lib/python3.5/site-packages/rest_framework/settings.py", line 170, in perform_import
    return import_from_string(val, setting_name)
  File "/home/python/.virtualenvs/py3_django/lib/python3.5/site-packages/rest_framework/settings.py", line 187, in import_from_string
    raise ImportError(msg)
ImportError: Could not import 'utils.exceptions.exception_handler' for API setting 'EXCEPTION_HANDLER'. ImportError: No module named 'utils'.
ERROR 2018-12-07 09:29:53,780 basehttp 124 "GET /authorizations/ HTTP/1.1" 500 120653
WARNING 2018-12-07 09:29:55,149 base 152 Not Found: /favicon.ico
WARNING 2018-12-07 09:29:55,153 basehttp 124 "GET /favicon.ico HTTP/1.1" 404 2864
WARNING 2018-12-07 09:32:44,516 basehttp 124 "POST /authorizations/ HTTP/1.1" 400 38
WARNING 2018-12-07 09:32:46,832 basehttp 124 "POST /authorizations/ HTTP/1.1" 400 38
WARNING 2018-12-07 09:32:49,307 basehttp 124 "POST /authorizations/ HTTP/1.1" 400 38
WARNING 2018-12-07 09:32:52,658 basehttp 124 "POST /authorizations/ HTTP/1.1" 400 38
INFO 2018-12-07 09:33:08,853 basehttp 124 "GET /usernames/python456/count/ HTTP/1.1" 200 34
INFO 2018-12-07 09:33:33,682 basehttp 124 "GET /mobiles/13123456789/count/ HTTP/1.1" 200 34
INFO 2018-12-07 09:33:33,738 basehttp 124 "GET /mobiles/13123456789/count/ HTTP/1.1" 200 34
INFO 2018-12-07 09:33:34,281 basehttp 124 "GET /sms_code/13123456789/ HTTP/1.1" 200 16
INFO 2018-12-07 09:34:03,960 basehttp 124 "OPTIONS /users/ HTTP/1.1" 200 0
INFO 2018-12-07 09:34:04,078 basehttp 124 "GET /mobiles/13123456789/count/ HTTP/1.1" 200 34
INFO 2018-12-07 09:34:04,088 basehttp 124 "GET /usernames/python456/count/ HTTP/1.1" 200 34
INFO 2018-12-07 09:34:04,470 basehttp 124 "POST /users/ HTTP/1.1" 201 232
INFO 2018-12-07 09:34:26,162 basehttp 124 "OPTIONS /authorizations/ HTTP/1.1" 200 0
WARNING 2018-12-07 09:34:26,173 basehttp 124 "POST /authorizations/ HTTP/1.1" 400 38
WARNING 2018-12-07 09:34:44,003 basehttp 124 "POST /authorizations/ HTTP/1.1" 400 38
INFO 2018-12-07 09:35:45,902 basehttp 124 "POST /authorizations/ HTTP/1.1" 200 179
INFO 2018-12-07 09:36:04,360 basehttp 124 "POST /authorizations/ HTTP/1.1" 200 179
INFO 2018-12-07 09:49:01,739 basehttp 124 "OPTIONS /authorizations/ HTTP/1.1" 200 0
INFO 2018-12-07 09:49:02,382 basehttp 124 "POST /authorizations/ HTTP/1.1" 200 214
INFO 2018-12-07 09:58:17,659 basehttp 124 "OPTIONS /authorizations/ HTTP/1.1" 200 0
INFO 2018-12-07 09:58:18,102 basehttp 124 "POST /authorizations/ HTTP/1.1" 200 214
INFO 2018-12-07 09:59:31,408 basehttp 124 "OPTIONS /authorizations/ HTTP/1.1" 200 0
INFO 2018-12-07 09:59:31,540 basehttp 124 "POST /authorizations/ HTTP/1.1" 200 230
WARNING 2018-12-08 14:12:13,745 base 152 Not Found: /oauth/qq/authorization/
WARNING 2018-12-08 14:12:13,783 basehttp 124 "GET /oauth/qq/authorization/?next=/ HTTP/1.1" 404 3080
WARNING 2018-12-08 14:12:15,224 base 152 Not Found: /oauth/qq/authorization/
WARNING 2018-12-08 14:12:15,228 basehttp 124 "GET /oauth/qq/authorization/?next=/ HTTP/1.1" 404 3080
WARNING 2018-12-08 14:12:19,478 base 152 Not Found: /oauth/qq/authorization/
WARNING 2018-12-08 14:12:19,486 basehttp 124 "GET /oauth/qq/authorization/?next=/ HTTP/1.1" 404 3080
WARNING 2018-12-08 14:12:21,074 base 152 Not Found: /oauth/qq/authorization/
WARNING 2018-12-08 14:12:21,078 basehttp 124 "GET /oauth/qq/authorization/?next=/ HTTP/1.1" 404 3080
WARNING 2018-12-08 14:12:21,268 base 152 Not Found: /oauth/qq/authorization/
WARNING 2018-12-08 14:12:21,271 basehttp 124 "GET /oauth/qq/authorization/?next=/ HTTP/1.1" 404 3080
WARNING 2018-12-08 14:12:21,439 base 152 Not Found: /oauth/qq/authorization/
WARNING 2018-12-08 14:12:21,442 basehttp 124 "GET /oauth/qq/authorization/?next=/ HTTP/1.1" 404 3080
WARNING 2018-12-08 14:12:21,602 base 152 Not Found: /oauth/qq/authorization/
WARNING 2018-12-08 14:12:21,607 basehttp 124 "GET /oauth/qq/authorization/?next=/ HTTP/1.1" 404 3080
WARNING 2018-12-08 14:12:21,797 base 152 Not Found: /oauth/qq/authorization/
WARNING 2018-12-08 14:12:21,800 basehttp 124 "GET /oauth/qq/authorization/?next=/ HTTP/1.1" 404 3080
INFO 2018-12-08 14:14:28,540 basehttp 124 "GET /oauth/qq/authorization/?next=/ HTTP/1.1" 200 195
WARNING 2018-12-08 14:14:45,634 base 152 Not Found: /oauth/qq/user/
WARNING 2018-12-08 14:14:45,636 basehttp 124 "GET /oauth/qq/user/?code=AE893A44D0D476BE43F0E2242A14D779 HTTP/1.1" 404 3085
WARNING 2018-12-08 20:53:11,969 base 152 Not Found: /oauth/qq/user/
WARNING 2018-12-08 20:53:12,018 basehttp 124 "GET /oauth/qq/user/?code=AE893A44D0D476BE43F0E2242A14D779 HTTP/1.1" 404 3250
INFO 2018-12-09 08:55:41,714 basehttp 124 "GET /oauth/qq/authorization/?next=/ HTTP/1.1" 200 195
ERROR 2018-12-09 08:55:51,507 exception 135 Internal Server Error: /oauth/qq/user/
Traceback (most recent call last):
  File "/home/python/.virtualenvs/py3_django/lib/python3.5/site-packages/rest_framework/views.py", line 480, in dispatch
    response = handler(request, *args, **kwargs)
  File "/home/python/Desktop/meiduo/demo/demo/apps/oauth/views.py", line 28, in get
    token = oauth.get_acess_token(code)
AttributeError: 'OAuthQQ' object has no attribute 'get_acess_token'

During handling of the above exception, another exception occurred:

Traceback (most recent call last):
  File "/home/python/.virtualenvs/py3_django/lib/python3.5/site-packages/rest_framework/settings.py", line 183, in import_from_string
    module = import_module(module_path)
  File "/home/python/.virtualenvs/py3_django/lib/python3.5/importlib/__init__.py", line 126, in import_module
    return _bootstrap._gcd_import(name[level:], package, level)
  File "<frozen importlib._bootstrap>", line 986, in _gcd_import
  File "<frozen importlib._bootstrap>", line 969, in _find_and_load
  File "<frozen importlib._bootstrap>", line 944, in _find_and_load_unlocked
  File "<frozen importlib._bootstrap>", line 222, in _call_with_frames_removed
  File "<frozen importlib._bootstrap>", line 986, in _gcd_import
  File "<frozen importlib._bootstrap>", line 969, in _find_and_load
  File "<frozen importlib._bootstrap>", line 956, in _find_and_load_unlocked
ImportError: No module named 'utils'

During handling of the above exception, another exception occurred:

Traceback (most recent call last):
  File "/home/python/.virtualenvs/py3_django/lib/python3.5/site-packages/django/core/handlers/exception.py", line 41, in inner
    response = get_response(request)
  File "/home/python/.virtualenvs/py3_django/lib/python3.5/site-packages/django/core/handlers/base.py", line 187, in _get_response
    response = self.process_exception_by_middleware(e, request)
  File "/home/python/.virtualenvs/py3_django/lib/python3.5/site-packages/django/core/handlers/base.py", line 185, in _get_response
    response = wrapped_callback(request, *callback_args, **callback_kwargs)
  File "/home/python/.virtualenvs/py3_django/lib/python3.5/site-packages/django/views/decorators/csrf.py", line 58, in wrapped_view
    return view_func(*args, **kwargs)
  File "/home/python/.virtualenvs/py3_django/lib/python3.5/site-packages/django/views/generic/base.py", line 68, in view
    return self.dispatch(request, *args, **kwargs)
  File "/home/python/.virtualenvs/py3_django/lib/python3.5/site-packages/rest_framework/views.py", line 483, in dispatch
    response = self.handle_exception(exc)
  File "/home/python/.virtualenvs/py3_django/lib/python3.5/site-packages/rest_framework/views.py", line 437, in handle_exception
    exception_handler = self.get_exception_handler()
  File "/home/python/.virtualenvs/py3_django/lib/python3.5/site-packages/rest_framework/views.py", line 288, in get_exception_handler
    return self.settings.EXCEPTION_HANDLER
  File "/home/python/.virtualenvs/py3_django/lib/python3.5/site-packages/rest_framework/settings.py", line 227, in __getattr__
    val = perform_import(val, attr)
  File "/home/python/.virtualenvs/py3_django/lib/python3.5/site-packages/rest_framework/settings.py", line 170, in perform_import
    return import_from_string(val, setting_name)
  File "/home/python/.virtualenvs/py3_django/lib/python3.5/site-packages/rest_framework/settings.py", line 187, in import_from_string
    raise ImportError(msg)
ImportError: Could not import 'utils.exceptions.exception_handler' for API setting 'EXCEPTION_HANDLER'. ImportError: No module named 'utils'.
ERROR 2018-12-09 08:55:52,090 basehttp 124 "GET /oauth/qq/user/?code=A581E0FD895FE10AEEC556E2B4544B06 HTTP/1.1" 500 121596
ERROR 2018-12-09 08:59:07,307 exception 135 Internal Server Error: /oauth/qq/user/
Traceback (most recent call last):
  File "/home/python/.virtualenvs/py3_django/lib/python3.5/site-packages/django/core/handlers/exception.py", line 41, in inner
    response = get_response(request)
  File "/home/python/.virtualenvs/py3_django/lib/python3.5/site-packages/django/core/handlers/base.py", line 187, in _get_response
    response = self.process_exception_by_middleware(e, request)
  File "/home/python/.virtualenvs/py3_django/lib/python3.5/site-packages/django/core/handlers/base.py", line 185, in _get_response
    response = wrapped_callback(request, *callback_args, **callback_kwargs)
  File "/home/python/.virtualenvs/py3_django/lib/python3.5/site-packages/django/views/decorators/csrf.py", line 58, in wrapped_view
    return view_func(*args, **kwargs)
  File "/home/python/.virtualenvs/py3_django/lib/python3.5/site-packages/django/views/generic/base.py", line 68, in view
    return self.dispatch(request, *args, **kwargs)
  File "/home/python/.virtualenvs/py3_django/lib/python3.5/site-packages/rest_framework/views.py", line 485, in dispatch
    self.response = self.finalize_response(request, response, *args, **kwargs)
  File "/home/python/.virtualenvs/py3_django/lib/python3.5/site-packages/rest_framework/views.py", line 400, in finalize_response
    % type(response)
AssertionError: Expected a `Response`, `HttpResponse` or `HttpStreamingResponse` to be returned from the view, but received a `<class 'NoneType'>`
ERROR 2018-12-09 08:59:07,579 basehttp 124 "GET /oauth/qq/user/?code=A581E0FD895FE10AEEC556E2B4544B06 HTTP/1.1" 500 88525
ERROR 2018-12-09 10:46:27,160 exception 135 Internal Server Error: /oauth/qq/user/
Traceback (most recent call last):
  File "/home/python/Desktop/meiduo/demo/demo/apps/oauth/views.py", line 45, in get
    qq = OauthQQ.objects.get(openid=openid)
  File "/home/python/.virtualenvs/py3_django/lib/python3.5/site-packages/django/db/models/manager.py", line 85, in manager_method
    return getattr(self.get_queryset(), name)(*args, **kwargs)
  File "/home/python/.virtualenvs/py3_django/lib/python3.5/site-packages/django/db/models/query.py", line 379, in get
    self.model._meta.object_name
oauth.models.DoesNotExist: OauthQQ matching query does not exist.

During handling of the above exception, another exception occurred:

Traceback (most recent call last):
  File "/home/python/.virtualenvs/py3_django/lib/python3.5/site-packages/rest_framework/views.py", line 480, in dispatch
    response = handler(request, *args, **kwargs)
  File "/home/python/Desktop/meiduo/demo/demo/apps/oauth/views.py", line 48, in get
    tjwss = TJWSS(settings.SECRT_KEY, constants.OPENID_EXPIRES)
  File "/home/python/.virtualenvs/py3_django/lib/python3.5/site-packages/django/conf/__init__.py", line 57, in __getattr__
    val = getattr(self._wrapped, name)
AttributeError: 'Settings' object has no attribute 'SECRT_KEY'

During handling of the above exception, another exception occurred:

Traceback (most recent call last):
  File "/home/python/.virtualenvs/py3_django/lib/python3.5/site-packages/rest_framework/settings.py", line 183, in import_from_string
    module = import_module(module_path)
  File "/home/python/.virtualenvs/py3_django/lib/python3.5/importlib/__init__.py", line 126, in import_module
    return _bootstrap._gcd_import(name[level:], package, level)
  File "<frozen importlib._bootstrap>", line 986, in _gcd_import
  File "<frozen importlib._bootstrap>", line 969, in _find_and_load
  File "<frozen importlib._bootstrap>", line 944, in _find_and_load_unlocked
  File "<frozen importlib._bootstrap>", line 222, in _call_with_frames_removed
  File "<frozen importlib._bootstrap>", line 986, in _gcd_import
  File "<frozen importlib._bootstrap>", line 969, in _find_and_load
  File "<frozen importlib._bootstrap>", line 956, in _find_and_load_unlocked
ImportError: No module named 'utils'

During handling of the above exception, another exception occurred:

Traceback (most recent call last):
  File "/home/python/.virtualenvs/py3_django/lib/python3.5/site-packages/django/core/handlers/exception.py", line 41, in inner
    response = get_response(request)
  File "/home/python/.virtualenvs/py3_django/lib/python3.5/site-packages/django/core/handlers/base.py", line 187, in _get_response
    response = self.process_exception_by_middleware(e, request)
  File "/home/python/.virtualenvs/py3_django/lib/python3.5/site-packages/django/core/handlers/base.py", line 185, in _get_response
    response = wrapped_callback(request, *callback_args, **callback_kwargs)
  File "/home/python/.virtualenvs/py3_django/lib/python3.5/site-packages/django/views/decorators/csrf.py", line 58, in wrapped_view
    return view_func(*args, **kwargs)
  File "/home/python/.virtualenvs/py3_django/lib/python3.5/site-packages/django/views/generic/base.py", line 68, in view
    return self.dispatch(request, *args, **kwargs)
  File "/home/python/.virtualenvs/py3_django/lib/python3.5/site-packages/rest_framework/views.py", line 483, in dispatch
    response = self.handle_exception(exc)
  File "/home/python/.virtualenvs/py3_django/lib/python3.5/site-packages/rest_framework/views.py", line 437, in handle_exception
    exception_handler = self.get_exception_handler()
  File "/home/python/.virtualenvs/py3_django/lib/python3.5/site-packages/rest_framework/views.py", line 288, in get_exception_handler
    return self.settings.EXCEPTION_HANDLER
  File "/home/python/.virtualenvs/py3_django/lib/python3.5/site-packages/rest_framework/settings.py", line 227, in __getattr__
    val = perform_import(val, attr)
  File "/home/python/.virtualenvs/py3_django/lib/python3.5/site-packages/rest_framework/settings.py", line 170, in perform_import
    return import_from_string(val, setting_name)
  File "/home/python/.virtualenvs/py3_django/lib/python3.5/site-packages/rest_framework/settings.py", line 187, in import_from_string
    raise ImportError(msg)
ImportError: Could not import 'utils.exceptions.exception_handler' for API setting 'EXCEPTION_HANDLER'. ImportError: No module named 'utils'.
ERROR 2018-12-09 10:46:27,830 basehttp 124 "GET /oauth/qq/user/?code=1478F603A65EE1EB9A80FB4C11B7F258 HTTP/1.1" 500 139632
INFO 2018-12-09 10:49:00,919 basehttp 124 "GET /oauth/qq/authorization/?next=/ HTTP/1.1" 200 195
INFO 2018-12-09 10:49:09,653 basehttp 124 "GET /oauth/qq/user/?code=46A7062C8391D934B5D7F579492FC7A0 HTTP/1.1" 200 190
INFO 2018-12-09 10:49:25,542 basehttp 124 "GET /sms_code/13112345678/ HTTP/1.1" 200 16
INFO 2018-12-09 10:49:51,368 basehttp 124 "OPTIONS /oauth/qq/user/ HTTP/1.1" 200 0
ERROR 2018-12-09 10:49:51,678 exception 135 Internal Server Error: /oauth/qq/user/
Traceback (most recent call last):
  File "/home/python/.virtualenvs/py3_django/lib/python3.5/site-packages/rest_framework/views.py", line 480, in dispatch
    response = handler(request, *args, **kwargs)
  File "/home/python/.virtualenvs/py3_django/lib/python3.5/site-packages/rest_framework/generics.py", line 192, in post
    return self.create(request, *args, **kwargs)
  File "/home/python/.virtualenvs/py3_django/lib/python3.5/site-packages/rest_framework/mixins.py", line 20, in create
    serializer.is_valid(raise_exception=True)
  File "/home/python/.virtualenvs/py3_django/lib/python3.5/site-packages/rest_framework/serializers.py", line 244, in is_valid
    raise ValidationError(self.errors)
rest_framework.exceptions.ValidationError: {'mobile': [ErrorDetail(string='手机号已存在', code='invalid')]}

During handling of the above exception, another exception occurred:

Traceback (most recent call last):
  File "/home/python/.virtualenvs/py3_django/lib/python3.5/site-packages/rest_framework/settings.py", line 183, in import_from_string
    module = import_module(module_path)
  File "/home/python/.virtualenvs/py3_django/lib/python3.5/importlib/__init__.py", line 126, in import_module
    return _bootstrap._gcd_import(name[level:], package, level)
  File "<frozen importlib._bootstrap>", line 986, in _gcd_import
  File "<frozen importlib._bootstrap>", line 969, in _find_and_load
  File "<frozen importlib._bootstrap>", line 944, in _find_and_load_unlocked
  File "<frozen importlib._bootstrap>", line 222, in _call_with_frames_removed
  File "<frozen importlib._bootstrap>", line 986, in _gcd_import
  File "<frozen importlib._bootstrap>", line 969, in _find_and_load
  File "<frozen importlib._bootstrap>", line 956, in _find_and_load_unlocked
ImportError: No module named 'utils'

During handling of the above exception, another exception occurred:

Traceback (most recent call last):
  File "/home/python/.virtualenvs/py3_django/lib/python3.5/site-packages/django/core/handlers/exception.py", line 41, in inner
    response = get_response(request)
  File "/home/python/.virtualenvs/py3_django/lib/python3.5/site-packages/django/core/handlers/base.py", line 187, in _get_response
    response = self.process_exception_by_middleware(e, request)
  File "/home/python/.virtualenvs/py3_django/lib/python3.5/site-packages/django/core/handlers/base.py", line 185, in _get_response
    response = wrapped_callback(request, *callback_args, **callback_kwargs)
  File "/home/python/.virtualenvs/py3_django/lib/python3.5/site-packages/django/views/decorators/csrf.py", line 58, in wrapped_view
    return view_func(*args, **kwargs)
  File "/home/python/.virtualenvs/py3_django/lib/python3.5/site-packages/django/views/generic/base.py", line 68, in view
    return self.dispatch(request, *args, **kwargs)
  File "/home/python/.virtualenvs/py3_django/lib/python3.5/site-packages/rest_framework/views.py", line 483, in dispatch
    response = self.handle_exception(exc)
  File "/home/python/.virtualenvs/py3_django/lib/python3.5/site-packages/rest_framework/views.py", line 437, in handle_exception
    exception_handler = self.get_exception_handler()
  File "/home/python/.virtualenvs/py3_django/lib/python3.5/site-packages/rest_framework/views.py", line 288, in get_exception_handler
    return self.settings.EXCEPTION_HANDLER
  File "/home/python/.virtualenvs/py3_django/lib/python3.5/site-packages/rest_framework/settings.py", line 227, in __getattr__
    val = perform_import(val, attr)
  File "/home/python/.virtualenvs/py3_django/lib/python3.5/site-packages/rest_framework/settings.py", line 170, in perform_import
    return import_from_string(val, setting_name)
  File "/home/python/.virtualenvs/py3_django/lib/python3.5/site-packages/rest_framework/settings.py", line 187, in import_from_string
    raise ImportError(msg)
ImportError: Could not import 'utils.exceptions.exception_handler' for API setting 'EXCEPTION_HANDLER'. ImportError: No module named 'utils'.
ERROR 2018-12-09 10:49:51,853 basehttp 124 "POST /oauth/qq/user/ HTTP/1.1" 500 130884
ERROR 2018-12-09 10:49:57,075 exception 135 Internal Server Error: /oauth/qq/user/
Traceback (most recent call last):
  File "/home/python/.virtualenvs/py3_django/lib/python3.5/site-packages/rest_framework/views.py", line 480, in dispatch
    response = handler(request, *args, **kwargs)
  File "/home/python/.virtualenvs/py3_django/lib/python3.5/site-packages/rest_framework/generics.py", line 192, in post
    return self.create(request, *args, **kwargs)
  File "/home/python/.virtualenvs/py3_django/lib/python3.5/site-packages/rest_framework/mixins.py", line 20, in create
    serializer.is_valid(raise_exception=True)
  File "/home/python/.virtualenvs/py3_django/lib/python3.5/site-packages/rest_framework/serializers.py", line 244, in is_valid
    raise ValidationError(self.errors)
rest_framework.exceptions.ValidationError: {'mobile': [ErrorDetail(string='手机号已存在', code='invalid')]}

During handling of the above exception, another exception occurred:

Traceback (most recent call last):
  File "/home/python/.virtualenvs/py3_django/lib/python3.5/site-packages/rest_framework/settings.py", line 183, in import_from_string
    module = import_module(module_path)
  File "/home/python/.virtualenvs/py3_django/lib/python3.5/importlib/__init__.py", line 126, in import_module
    return _bootstrap._gcd_import(name[level:], package, level)
  File "<frozen importlib._bootstrap>", line 986, in _gcd_import
  File "<frozen importlib._bootstrap>", line 969, in _find_and_load
  File "<frozen importlib._bootstrap>", line 944, in _find_and_load_unlocked
  File "<frozen importlib._bootstrap>", line 222, in _call_with_frames_removed
  File "<frozen importlib._bootstrap>", line 986, in _gcd_import
  File "<frozen importlib._bootstrap>", line 969, in _find_and_load
  File "<frozen importlib._bootstrap>", line 956, in _find_and_load_unlocked
ImportError: No module named 'utils'

During handling of the above exception, another exception occurred:

Traceback (most recent call last):
  File "/home/python/.virtualenvs/py3_django/lib/python3.5/site-packages/django/core/handlers/exception.py", line 41, in inner
    response = get_response(request)
  File "/home/python/.virtualenvs/py3_django/lib/python3.5/site-packages/django/core/handlers/base.py", line 187, in _get_response
    response = self.process_exception_by_middleware(e, request)
  File "/home/python/.virtualenvs/py3_django/lib/python3.5/site-packages/django/core/handlers/base.py", line 185, in _get_response
    response = wrapped_callback(request, *callback_args, **callback_kwargs)
  File "/home/python/.virtualenvs/py3_django/lib/python3.5/site-packages/django/views/decorators/csrf.py", line 58, in wrapped_view
    return view_func(*args, **kwargs)
  File "/home/python/.virtualenvs/py3_django/lib/python3.5/site-packages/django/views/generic/base.py", line 68, in view
    return self.dispatch(request, *args, **kwargs)
  File "/home/python/.virtualenvs/py3_django/lib/python3.5/site-packages/rest_framework/views.py", line 483, in dispatch
    response = self.handle_exception(exc)
  File "/home/python/.virtualenvs/py3_django/lib/python3.5/site-packages/rest_framework/views.py", line 437, in handle_exception
    exception_handler = self.get_exception_handler()
  File "/home/python/.virtualenvs/py3_django/lib/python3.5/site-packages/rest_framework/views.py", line 288, in get_exception_handler
    return self.settings.EXCEPTION_HANDLER
  File "/home/python/.virtualenvs/py3_django/lib/python3.5/site-packages/rest_framework/settings.py", line 227, in __getattr__
    val = perform_import(val, attr)
  File "/home/python/.virtualenvs/py3_django/lib/python3.5/site-packages/rest_framework/settings.py", line 170, in perform_import
    return import_from_string(val, setting_name)
  File "/home/python/.virtualenvs/py3_django/lib/python3.5/site-packages/rest_framework/settings.py", line 187, in import_from_string
    raise ImportError(msg)
ImportError: Could not import 'utils.exceptions.exception_handler' for API setting 'EXCEPTION_HANDLER'. ImportError: No module named 'utils'.
ERROR 2018-12-09 10:49:57,188 basehttp 124 "POST /oauth/qq/user/ HTTP/1.1" 500 130884
ERROR 2018-12-09 10:51:02,667 exception 135 Internal Server Error: /oauth/qq/user/
Traceback (most recent call last):
  File "/home/python/.virtualenvs/py3_django/lib/python3.5/site-packages/rest_framework/views.py", line 480, in dispatch
    response = handler(request, *args, **kwargs)
  File "/home/python/.virtualenvs/py3_django/lib/python3.5/site-packages/rest_framework/generics.py", line 192, in post
    return self.create(request, *args, **kwargs)
  File "/home/python/.virtualenvs/py3_django/lib/python3.5/site-packages/rest_framework/mixins.py", line 20, in create
    serializer.is_valid(raise_exception=True)
  File "/home/python/.virtualenvs/py3_django/lib/python3.5/site-packages/rest_framework/serializers.py", line 244, in is_valid
    raise ValidationError(self.errors)
rest_framework.exceptions.ValidationError: {'non_field_errors': [ErrorDetail(string='短信验证码已过期', code='invalid')]}

During handling of the above exception, another exception occurred:

Traceback (most recent call last):
  File "/home/python/.virtualenvs/py3_django/lib/python3.5/site-packages/rest_framework/settings.py", line 183, in import_from_string
    module = import_module(module_path)
  File "/home/python/.virtualenvs/py3_django/lib/python3.5/importlib/__init__.py", line 126, in import_module
    return _bootstrap._gcd_import(name[level:], package, level)
  File "<frozen importlib._bootstrap>", line 986, in _gcd_import
  File "<frozen importlib._bootstrap>", line 969, in _find_and_load
  File "<frozen importlib._bootstrap>", line 944, in _find_and_load_unlocked
  File "<frozen importlib._bootstrap>", line 222, in _call_with_frames_removed
  File "<frozen importlib._bootstrap>", line 986, in _gcd_import
  File "<frozen importlib._bootstrap>", line 969, in _find_and_load
  File "<frozen importlib._bootstrap>", line 956, in _find_and_load_unlocked
ImportError: No module named 'utils'

During handling of the above exception, another exception occurred:

Traceback (most recent call last):
  File "/home/python/.virtualenvs/py3_django/lib/python3.5/site-packages/django/core/handlers/exception.py", line 41, in inner
    response = get_response(request)
  File "/home/python/.virtualenvs/py3_django/lib/python3.5/site-packages/django/core/handlers/base.py", line 187, in _get_response
    response = self.process_exception_by_middleware(e, request)
  File "/home/python/.virtualenvs/py3_django/lib/python3.5/site-packages/django/core/handlers/base.py", line 185, in _get_response
    response = wrapped_callback(request, *callback_args, **callback_kwargs)
  File "/home/python/.virtualenvs/py3_django/lib/python3.5/site-packages/django/views/decorators/csrf.py", line 58, in wrapped_view
    return view_func(*args, **kwargs)
  File "/home/python/.virtualenvs/py3_django/lib/python3.5/site-packages/django/views/generic/base.py", line 68, in view
    return self.dispatch(request, *args, **kwargs)
  File "/home/python/.virtualenvs/py3_django/lib/python3.5/site-packages/rest_framework/views.py", line 483, in dispatch
    response = self.handle_exception(exc)
  File "/home/python/.virtualenvs/py3_django/lib/python3.5/site-packages/rest_framework/views.py", line 437, in handle_exception
    exception_handler = self.get_exception_handler()
  File "/home/python/.virtualenvs/py3_django/lib/python3.5/site-packages/rest_framework/views.py", line 288, in get_exception_handler
    return self.settings.EXCEPTION_HANDLER
  File "/home/python/.virtualenvs/py3_django/lib/python3.5/site-packages/rest_framework/settings.py", line 227, in __getattr__
    val = perform_import(val, attr)
  File "/home/python/.virtualenvs/py3_django/lib/python3.5/site-packages/rest_framework/settings.py", line 170, in perform_import
    return import_from_string(val, setting_name)
  File "/home/python/.virtualenvs/py3_django/lib/python3.5/site-packages/rest_framework/settings.py", line 187, in import_from_string
    raise ImportError(msg)
ImportError: Could not import 'utils.exceptions.exception_handler' for API setting 'EXCEPTION_HANDLER'. ImportError: No module named 'utils'.
ERROR 2018-12-09 10:51:02,827 basehttp 124 "POST /oauth/qq/user/ HTTP/1.1" 500 130932
INFO 2018-12-09 10:52:09,793 basehttp 124 "GET /sms_code/13134567890/ HTTP/1.1" 200 16
ERROR 2018-12-09 10:52:27,530 exception 135 Internal Server Error: /oauth/qq/user/
Traceback (most recent call last):
  File "/home/python/.virtualenvs/py3_django/lib/python3.5/site-packages/rest_framework/views.py", line 480, in dispatch
    response = handler(request, *args, **kwargs)
  File "/home/python/.virtualenvs/py3_django/lib/python3.5/site-packages/rest_framework/generics.py", line 192, in post
    return self.create(request, *args, **kwargs)
  File "/home/python/.virtualenvs/py3_django/lib/python3.5/site-packages/rest_framework/mixins.py", line 20, in create
    serializer.is_valid(raise_exception=True)
  File "/home/python/.virtualenvs/py3_django/lib/python3.5/site-packages/rest_framework/serializers.py", line 244, in is_valid
    raise ValidationError(self.errors)
rest_framework.exceptions.ValidationError: {'non_field_errors': [ErrorDetail(string='短信验证码错误', code='invalid')]}

During handling of the above exception, another exception occurred:

Traceback (most recent call last):
  File "/home/python/.virtualenvs/py3_django/lib/python3.5/site-packages/rest_framework/settings.py", line 183, in import_from_string
    module = import_module(module_path)
  File "/home/python/.virtualenvs/py3_django/lib/python3.5/importlib/__init__.py", line 126, in import_module
    return _bootstrap._gcd_import(name[level:], package, level)
  File "<frozen importlib._bootstrap>", line 986, in _gcd_import
  File "<frozen importlib._bootstrap>", line 969, in _find_and_load
  File "<frozen importlib._bootstrap>", line 944, in _find_and_load_unlocked
  File "<frozen importlib._bootstrap>", line 222, in _call_with_frames_removed
  File "<frozen importlib._bootstrap>", line 986, in _gcd_import
  File "<frozen importlib._bootstrap>", line 969, in _find_and_load
  File "<frozen importlib._bootstrap>", line 956, in _find_and_load_unlocked
ImportError: No module named 'utils'

During handling of the above exception, another exception occurred:

Traceback (most recent call last):
  File "/home/python/.virtualenvs/py3_django/lib/python3.5/site-packages/django/core/handlers/exception.py", line 41, in inner
    response = get_response(request)
  File "/home/python/.virtualenvs/py3_django/lib/python3.5/site-packages/django/core/handlers/base.py", line 187, in _get_response
    response = self.process_exception_by_middleware(e, request)
  File "/home/python/.virtualenvs/py3_django/lib/python3.5/site-packages/django/core/handlers/base.py", line 185, in _get_response
    response = wrapped_callback(request, *callback_args, **callback_kwargs)
  File "/home/python/.virtualenvs/py3_django/lib/python3.5/site-packages/django/views/decorators/csrf.py", line 58, in wrapped_view
    return view_func(*args, **kwargs)
  File "/home/python/.virtualenvs/py3_django/lib/python3.5/site-packages/django/views/generic/base.py", line 68, in view
    return self.dispatch(request, *args, **kwargs)
  File "/home/python/.virtualenvs/py3_django/lib/python3.5/site-packages/rest_framework/views.py", line 483, in dispatch
    response = self.handle_exception(exc)
  File "/home/python/.virtualenvs/py3_django/lib/python3.5/site-packages/rest_framework/views.py", line 437, in handle_exception
    exception_handler = self.get_exception_handler()
  File "/home/python/.virtualenvs/py3_django/lib/python3.5/site-packages/rest_framework/views.py", line 288, in get_exception_handler
    return self.settings.EXCEPTION_HANDLER
  File "/home/python/.virtualenvs/py3_django/lib/python3.5/site-packages/rest_framework/settings.py", line 227, in __getattr__
    val = perform_import(val, attr)
  File "/home/python/.virtualenvs/py3_django/lib/python3.5/site-packages/rest_framework/settings.py", line 170, in perform_import
    return import_from_string(val, setting_name)
  File "/home/python/.virtualenvs/py3_django/lib/python3.5/site-packages/rest_framework/settings.py", line 187, in import_from_string
    raise ImportError(msg)
ImportError: Could not import 'utils.exceptions.exception_handler' for API setting 'EXCEPTION_HANDLER'. ImportError: No module named 'utils'.
ERROR 2018-12-09 10:52:27,648 basehttp 124 "POST /oauth/qq/user/ HTTP/1.1" 500 130923
ERROR 2018-12-09 10:52:31,577 exception 135 Internal Server Error: /oauth/qq/user/
Traceback (most recent call last):
  File "/home/python/.virtualenvs/py3_django/lib/python3.5/site-packages/rest_framework/views.py", line 480, in dispatch
    response = handler(request, *args, **kwargs)
  File "/home/python/.virtualenvs/py3_django/lib/python3.5/site-packages/rest_framework/generics.py", line 192, in post
    return self.create(request, *args, **kwargs)
  File "/home/python/.virtualenvs/py3_django/lib/python3.5/site-packages/rest_framework/mixins.py", line 20, in create
    serializer.is_valid(raise_exception=True)
  File "/home/python/.virtualenvs/py3_django/lib/python3.5/site-packages/rest_framework/serializers.py", line 244, in is_valid
    raise ValidationError(self.errors)
rest_framework.exceptions.ValidationError: {'non_field_errors': [ErrorDetail(string='短信验证码错误', code='invalid')]}

During handling of the above exception, another exception occurred:

Traceback (most recent call last):
  File "/home/python/.virtualenvs/py3_django/lib/python3.5/site-packages/rest_framework/settings.py", line 183, in import_from_string
    module = import_module(module_path)
  File "/home/python/.virtualenvs/py3_django/lib/python3.5/importlib/__init__.py", line 126, in import_module
    return _bootstrap._gcd_import(name[level:], package, level)
  File "<frozen importlib._bootstrap>", line 986, in _gcd_import
  File "<frozen importlib._bootstrap>", line 969, in _find_and_load
  File "<frozen importlib._bootstrap>", line 944, in _find_and_load_unlocked
  File "<frozen importlib._bootstrap>", line 222, in _call_with_frames_removed
  File "<frozen importlib._bootstrap>", line 986, in _gcd_import
  File "<frozen importlib._bootstrap>", line 969, in _find_and_load
  File "<frozen importlib._bootstrap>", line 956, in _find_and_load_unlocked
ImportError: No module named 'utils'

During handling of the above exception, another exception occurred:

Traceback (most recent call last):
  File "/home/python/.virtualenvs/py3_django/lib/python3.5/site-packages/django/core/handlers/exception.py", line 41, in inner
    response = get_response(request)
  File "/home/python/.virtualenvs/py3_django/lib/python3.5/site-packages/django/core/handlers/base.py", line 187, in _get_response
    response = self.process_exception_by_middleware(e, request)
  File "/home/python/.virtualenvs/py3_django/lib/python3.5/site-packages/django/core/handlers/base.py", line 185, in _get_response
    response = wrapped_callback(request, *callback_args, **callback_kwargs)
  File "/home/python/.virtualenvs/py3_django/lib/python3.5/site-packages/django/views/decorators/csrf.py", line 58, in wrapped_view
    return view_func(*args, **kwargs)
  File "/home/python/.virtualenvs/py3_django/lib/python3.5/site-packages/django/views/generic/base.py", line 68, in view
    return self.dispatch(request, *args, **kwargs)
  File "/home/python/.virtualenvs/py3_django/lib/python3.5/site-packages/rest_framework/views.py", line 483, in dispatch
    response = self.handle_exception(exc)
  File "/home/python/.virtualenvs/py3_django/lib/python3.5/site-packages/rest_framework/views.py", line 437, in handle_exception
    exception_handler = self.get_exception_handler()
  File "/home/python/.virtualenvs/py3_django/lib/python3.5/site-packages/rest_framework/views.py", line 288, in get_exception_handler
    return self.settings.EXCEPTION_HANDLER
  File "/home/python/.virtualenvs/py3_django/lib/python3.5/site-packages/rest_framework/settings.py", line 227, in __getattr__
    val = perform_import(val, attr)
  File "/home/python/.virtualenvs/py3_django/lib/python3.5/site-packages/rest_framework/settings.py", line 170, in perform_import
    return import_from_string(val, setting_name)
  File "/home/python/.virtualenvs/py3_django/lib/python3.5/site-packages/rest_framework/settings.py", line 187, in import_from_string
    raise ImportError(msg)
ImportError: Could not import 'utils.exceptions.exception_handler' for API setting 'EXCEPTION_HANDLER'. ImportError: No module named 'utils'.
ERROR 2018-12-09 10:52:31,685 basehttp 124 "POST /oauth/qq/user/ HTTP/1.1" 500 130923
ERROR 2018-12-09 10:54:09,034 exception 135 Internal Server Error: /oauth/qq/user/
Traceback (most recent call last):
  File "/home/python/.virtualenvs/py3_django/lib/python3.5/site-packages/rest_framework/views.py", line 480, in dispatch
    response = handler(request, *args, **kwargs)
  File "/home/python/.virtualenvs/py3_django/lib/python3.5/site-packages/rest_framework/generics.py", line 192, in post
    return self.create(request, *args, **kwargs)
  File "/home/python/.virtualenvs/py3_django/lib/python3.5/site-packages/rest_framework/mixins.py", line 21, in create
    self.perform_create(serializer)
  File "/home/python/.virtualenvs/py3_django/lib/python3.5/site-packages/rest_framework/mixins.py", line 26, in perform_create
    serializer.save()
  File "/home/python/.virtualenvs/py3_django/lib/python3.5/site-packages/rest_framework/serializers.py", line 214, in save
    self.instance = self.create(validated_data)
  File "/home/python/Desktop/meiduo/demo/demo/apps/oauth/serializers.py", line 65, in create
    password = validated_data('password')
TypeError: 'dict' object is not callable

During handling of the above exception, another exception occurred:

Traceback (most recent call last):
  File "/home/python/.virtualenvs/py3_django/lib/python3.5/site-packages/rest_framework/settings.py", line 183, in import_from_string
    module = import_module(module_path)
  File "/home/python/.virtualenvs/py3_django/lib/python3.5/importlib/__init__.py", line 126, in import_module
    return _bootstrap._gcd_import(name[level:], package, level)
  File "<frozen importlib._bootstrap>", line 986, in _gcd_import
  File "<frozen importlib._bootstrap>", line 969, in _find_and_load
  File "<frozen importlib._bootstrap>", line 944, in _find_and_load_unlocked
  File "<frozen importlib._bootstrap>", line 222, in _call_with_frames_removed
  File "<frozen importlib._bootstrap>", line 986, in _gcd_import
  File "<frozen importlib._bootstrap>", line 969, in _find_and_load
  File "<frozen importlib._bootstrap>", line 956, in _find_and_load_unlocked
ImportError: No module named 'utils'

During handling of the above exception, another exception occurred:

Traceback (most recent call last):
  File "/home/python/.virtualenvs/py3_django/lib/python3.5/site-packages/django/core/handlers/exception.py", line 41, in inner
    response = get_response(request)
  File "/home/python/.virtualenvs/py3_django/lib/python3.5/site-packages/django/core/handlers/base.py", line 187, in _get_response
    response = self.process_exception_by_middleware(e, request)
  File "/home/python/.virtualenvs/py3_django/lib/python3.5/site-packages/django/core/handlers/base.py", line 185, in _get_response
    response = wrapped_callback(request, *callback_args, **callback_kwargs)
  File "/home/python/.virtualenvs/py3_django/lib/python3.5/site-packages/django/views/decorators/csrf.py", line 58, in wrapped_view
    return view_func(*args, **kwargs)
  File "/home/python/.virtualenvs/py3_django/lib/python3.5/site-packages/django/views/generic/base.py", line 68, in view
    return self.dispatch(request, *args, **kwargs)
  File "/home/python/.virtualenvs/py3_django/lib/python3.5/site-packages/rest_framework/views.py", line 483, in dispatch
    response = self.handle_exception(exc)
  File "/home/python/.virtualenvs/py3_django/lib/python3.5/site-packages/rest_framework/views.py", line 437, in handle_exception
    exception_handler = self.get_exception_handler()
  File "/home/python/.virtualenvs/py3_django/lib/python3.5/site-packages/rest_framework/views.py", line 288, in get_exception_handler
    return self.settings.EXCEPTION_HANDLER
  File "/home/python/.virtualenvs/py3_django/lib/python3.5/site-packages/rest_framework/settings.py", line 227, in __getattr__
    val = perform_import(val, attr)
  File "/home/python/.virtualenvs/py3_django/lib/python3.5/site-packages/rest_framework/settings.py", line 170, in perform_import
    return import_from_string(val, setting_name)
  File "/home/python/.virtualenvs/py3_django/lib/python3.5/site-packages/rest_framework/settings.py", line 187, in import_from_string
    raise ImportError(msg)
ImportError: Could not import 'utils.exceptions.exception_handler' for API setting 'EXCEPTION_HANDLER'. ImportError: No module named 'utils'.
ERROR 2018-12-09 10:54:09,169 basehttp 124 "POST /oauth/qq/user/ HTTP/1.1" 500 140705
INFO 2018-12-09 10:55:25,487 basehttp 124 "POST /oauth/qq/user/ HTTP/1.1" 201 222
INFO 2018-12-09 11:33:00,407 basehttp 124 "OPTIONS /user/ HTTP/1.1" 200 0
ERROR 2018-12-09 11:33:00,913 exception 135 Internal Server Error: /user/
Traceback (most recent call last):
  File "/home/python/.virtualenvs/py3_django/lib/python3.5/site-packages/django/db/backends/utils.py", line 65, in execute
    return self.cursor.execute(sql, params)
  File "/home/python/.virtualenvs/py3_django/lib/python3.5/site-packages/django/db/backends/mysql/base.py", line 101, in execute
    return self.cursor.execute(query, args)
  File "/home/python/.virtualenvs/py3_django/lib/python3.5/site-packages/pymysql/cursors.py", line 170, in execute
    result = self._query(query)
  File "/home/python/.virtualenvs/py3_django/lib/python3.5/site-packages/pymysql/cursors.py", line 328, in _query
    conn.query(q)
  File "/home/python/.virtualenvs/py3_django/lib/python3.5/site-packages/pymysql/connections.py", line 516, in query
    self._affected_rows = self._read_query_result(unbuffered=unbuffered)
  File "/home/python/.virtualenvs/py3_django/lib/python3.5/site-packages/pymysql/connections.py", line 727, in _read_query_result
    result.read()
  File "/home/python/.virtualenvs/py3_django/lib/python3.5/site-packages/pymysql/connections.py", line 1066, in read
    first_packet = self.connection._read_packet()
  File "/home/python/.virtualenvs/py3_django/lib/python3.5/site-packages/pymysql/connections.py", line 683, in _read_packet
    packet.check_error()
  File "/home/python/.virtualenvs/py3_django/lib/python3.5/site-packages/pymysql/protocol.py", line 220, in check_error
    err.raise_mysql_exception(self._data)
  File "/home/python/.virtualenvs/py3_django/lib/python3.5/site-packages/pymysql/err.py", line 109, in raise_mysql_exception
    raise errorclass(errno, errval)
pymysql.err.InternalError: (1054, "Unknown column 'users_user.email_active' in 'field list'")

The above exception was the direct cause of the following exception:

Traceback (most recent call last):
  File "/home/python/.virtualenvs/py3_django/lib/python3.5/site-packages/rest_framework/views.py", line 471, in dispatch
    self.initial(request, *args, **kwargs)
  File "/home/python/.virtualenvs/py3_django/lib/python3.5/site-packages/rest_framework/views.py", line 388, in initial
    self.perform_authentication(request)
  File "/home/python/.virtualenvs/py3_django/lib/python3.5/site-packages/rest_framework/views.py", line 314, in perform_authentication
    request.user
  File "/home/python/.virtualenvs/py3_django/lib/python3.5/site-packages/rest_framework/request.py", line 222, in user
    self._authenticate()
  File "/home/python/.virtualenvs/py3_django/lib/python3.5/site-packages/rest_framework/request.py", line 375, in _authenticate
    user_auth_tuple = authenticator.authenticate(self)
  File "/home/python/.virtualenvs/py3_django/lib/python3.5/site-packages/rest_framework_jwt/authentication.py", line 43, in authenticate
    user = self.authenticate_credentials(payload)
  File "/home/python/.virtualenvs/py3_django/lib/python3.5/site-packages/rest_framework_jwt/authentication.py", line 59, in authenticate_credentials
    user = User.objects.get_by_natural_key(username)
  File "/home/python/.virtualenvs/py3_django/lib/python3.5/site-packages/django/contrib/auth/base_user.py", line 48, in get_by_natural_key
    return self.get(**{self.model.USERNAME_FIELD: username})
  File "/home/python/.virtualenvs/py3_django/lib/python3.5/site-packages/django/db/models/manager.py", line 85, in manager_method
    return getattr(self.get_queryset(), name)(*args, **kwargs)
  File "/home/python/.virtualenvs/py3_django/lib/python3.5/site-packages/django/db/models/query.py", line 373, in get
    num = len(clone)
  File "/home/python/.virtualenvs/py3_django/lib/python3.5/site-packages/django/db/models/query.py", line 232, in __len__
    self._fetch_all()
  File "/home/python/.virtualenvs/py3_django/lib/python3.5/site-packages/django/db/models/query.py", line 1102, in _fetch_all
    self._result_cache = list(self._iterable_class(self))
  File "/home/python/.virtualenvs/py3_django/lib/python3.5/site-packages/django/db/models/query.py", line 53, in __iter__
    results = compiler.execute_sql(chunked_fetch=self.chunked_fetch)
  File "/home/python/.virtualenvs/py3_django/lib/python3.5/site-packages/django/db/models/sql/compiler.py", line 876, in execute_sql
    cursor.execute(sql, params)
  File "/home/python/.virtualenvs/py3_django/lib/python3.5/site-packages/django/db/backends/utils.py", line 80, in execute
    return super(CursorDebugWrapper, self).execute(sql, params)
  File "/home/python/.virtualenvs/py3_django/lib/python3.5/site-packages/django/db/backends/utils.py", line 65, in execute
    return self.cursor.execute(sql, params)
  File "/home/python/.virtualenvs/py3_django/lib/python3.5/site-packages/django/db/utils.py", line 94, in __exit__
    six.reraise(dj_exc_type, dj_exc_value, traceback)
  File "/home/python/.virtualenvs/py3_django/lib/python3.5/site-packages/django/utils/six.py", line 685, in reraise
    raise value.with_traceback(tb)
  File "/home/python/.virtualenvs/py3_django/lib/python3.5/site-packages/django/db/backends/utils.py", line 65, in execute
    return self.cursor.execute(sql, params)
  File "/home/python/.virtualenvs/py3_django/lib/python3.5/site-packages/django/db/backends/mysql/base.py", line 101, in execute
    return self.cursor.execute(query, args)
  File "/home/python/.virtualenvs/py3_django/lib/python3.5/site-packages/pymysql/cursors.py", line 170, in execute
    result = self._query(query)
  File "/home/python/.virtualenvs/py3_django/lib/python3.5/site-packages/pymysql/cursors.py", line 328, in _query
    conn.query(q)
  File "/home/python/.virtualenvs/py3_django/lib/python3.5/site-packages/pymysql/connections.py", line 516, in query
    self._affected_rows = self._read_query_result(unbuffered=unbuffered)
  File "/home/python/.virtualenvs/py3_django/lib/python3.5/site-packages/pymysql/connections.py", line 727, in _read_query_result
    result.read()
  File "/home/python/.virtualenvs/py3_django/lib/python3.5/site-packages/pymysql/connections.py", line 1066, in read
    first_packet = self.connection._read_packet()
  File "/home/python/.virtualenvs/py3_django/lib/python3.5/site-packages/pymysql/connections.py", line 683, in _read_packet
    packet.check_error()
  File "/home/python/.virtualenvs/py3_django/lib/python3.5/site-packages/pymysql/protocol.py", line 220, in check_error
    err.raise_mysql_exception(self._data)
  File "/home/python/.virtualenvs/py3_django/lib/python3.5/site-packages/pymysql/err.py", line 109, in raise_mysql_exception
    raise errorclass(errno, errval)
django.db.utils.InternalError: (1054, "Unknown column 'users_user.email_active' in 'field list'")

During handling of the above exception, another exception occurred:

Traceback (most recent call last):
  File "/home/python/.virtualenvs/py3_django/lib/python3.5/site-packages/rest_framework/settings.py", line 183, in import_from_string
    module = import_module(module_path)
  File "/home/python/.virtualenvs/py3_django/lib/python3.5/importlib/__init__.py", line 126, in import_module
    return _bootstrap._gcd_import(name[level:], package, level)
  File "<frozen importlib._bootstrap>", line 986, in _gcd_import
  File "<frozen importlib._bootstrap>", line 969, in _find_and_load
  File "<frozen importlib._bootstrap>", line 944, in _find_and_load_unlocked
  File "<frozen importlib._bootstrap>", line 222, in _call_with_frames_removed
  File "<frozen importlib._bootstrap>", line 986, in _gcd_import
  File "<frozen importlib._bootstrap>", line 969, in _find_and_load
  File "<frozen importlib._bootstrap>", line 956, in _find_and_load_unlocked
ImportError: No module named 'utils'

During handling of the above exception, another exception occurred:

Traceback (most recent call last):
  File "/home/python/.virtualenvs/py3_django/lib/python3.5/site-packages/django/core/handlers/exception.py", line 41, in inner
    response = get_response(request)
  File "/home/python/.virtualenvs/py3_django/lib/python3.5/site-packages/django/core/handlers/base.py", line 187, in _get_response
    response = self.process_exception_by_middleware(e, request)
  File "/home/python/.virtualenvs/py3_django/lib/python3.5/site-packages/django/core/handlers/base.py", line 185, in _get_response
    response = wrapped_callback(request, *callback_args, **callback_kwargs)
  File "/home/python/.virtualenvs/py3_django/lib/python3.5/site-packages/django/views/decorators/csrf.py", line 58, in wrapped_view
    return view_func(*args, **kwargs)
  File "/home/python/.virtualenvs/py3_django/lib/python3.5/site-packages/django/views/generic/base.py", line 68, in view
    return self.dispatch(request, *args, **kwargs)
  File "/home/python/.virtualenvs/py3_django/lib/python3.5/site-packages/rest_framework/views.py", line 483, in dispatch
    response = self.handle_exception(exc)
  File "/home/python/.virtualenvs/py3_django/lib/python3.5/site-packages/rest_framework/views.py", line 437, in handle_exception
    exception_handler = self.get_exception_handler()
  File "/home/python/.virtualenvs/py3_django/lib/python3.5/site-packages/rest_framework/views.py", line 288, in get_exception_handler
    return self.settings.EXCEPTION_HANDLER
  File "/home/python/.virtualenvs/py3_django/lib/python3.5/site-packages/rest_framework/settings.py", line 227, in __getattr__
    val = perform_import(val, attr)
  File "/home/python/.virtualenvs/py3_django/lib/python3.5/site-packages/rest_framework/settings.py", line 170, in perform_import
    return import_from_string(val, setting_name)
  File "/home/python/.virtualenvs/py3_django/lib/python3.5/site-packages/rest_framework/settings.py", line 187, in import_from_string
    raise ImportError(msg)
ImportError: Could not import 'utils.exceptions.exception_handler' for API setting 'EXCEPTION_HANDLER'. ImportError: No module named 'utils'.
ERROR 2018-12-09 11:33:01,898 basehttp 124 "GET /user/ HTTP/1.1" 500 277646
INFO 2018-12-09 11:33:19,315 basehttp 124 "OPTIONS /authorizations/ HTTP/1.1" 200 0
WARNING 2018-12-09 11:33:19,406 basehttp 124 "POST /authorizations/ HTTP/1.1" 400 67
WARNING 2018-12-09 11:33:27,999 basehttp 124 "POST /authorizations/ HTTP/1.1" 400 67
INFO 2018-12-09 11:34:14,250 basehttp 124 "OPTIONS /authorizations/ HTTP/1.1" 200 0
WARNING 2018-12-09 11:34:14,414 basehttp 124 "POST /authorizations/ HTTP/1.1" 400 67
INFO 2018-12-09 11:34:15,803 basehttp 124 "OPTIONS /authorizations/ HTTP/1.1" 200 0
WARNING 2018-12-09 11:34:15,956 basehttp 124 "POST /authorizations/ HTTP/1.1" 400 67
INFO 2018-12-09 11:34:16,198 basehttp 124 "OPTIONS /authorizations/ HTTP/1.1" 200 0
WARNING 2018-12-09 11:34:16,232 basehttp 124 "POST /authorizations/ HTTP/1.1" 400 67
INFO 2018-12-09 11:34:16,461 basehttp 124 "OPTIONS /authorizations/ HTTP/1.1" 200 0
WARNING 2018-12-09 11:34:16,487 basehttp 124 "POST /authorizations/ HTTP/1.1" 400 67
INFO 2018-12-09 11:37:43,485 basehttp 124 "OPTIONS /authorizations/ HTTP/1.1" 200 0
WARNING 2018-12-09 11:37:43,701 basehttp 124 "POST /authorizations/ HTTP/1.1" 400 67
INFO 2018-12-09 11:38:19,338 basehttp 124 "OPTIONS /authorizations/ HTTP/1.1" 200 0
WARNING 2018-12-09 11:38:19,440 basehttp 124 "POST /authorizations/ HTTP/1.1" 400 67
INFO 2018-12-09 11:38:20,314 basehttp 124 "OPTIONS /authorizations/ HTTP/1.1" 200 0
WARNING 2018-12-09 11:38:20,403 basehttp 124 "POST /authorizations/ HTTP/1.1" 400 67
INFO 2018-12-09 11:39:13,719 basehttp 124 "OPTIONS /authorizations/ HTTP/1.1" 200 0
WARNING 2018-12-09 11:39:13,832 basehttp 124 "POST /authorizations/ HTTP/1.1" 400 67
INFO 2018-12-09 11:39:26,422 basehttp 124 "OPTIONS /authorizations/ HTTP/1.1" 200 0
WARNING 2018-12-09 11:39:26,636 basehttp 124 "POST /authorizations/ HTTP/1.1" 400 67
INFO 2018-12-09 11:47:41,590 basehttp 124 "GET /oauth/qq/authorization/?next=/ HTTP/1.1" 200 195
ERROR 2018-12-09 11:47:59,345 exception 135 Internal Server Error: /oauth/qq/user/
Traceback (most recent call last):
  File "/home/python/.virtualenvs/py3_django/lib/python3.5/site-packages/django/db/models/fields/related_descriptors.py", line 178, in __get__
    rel_obj = getattr(instance, self.cache_name)
AttributeError: 'OauthQQ' object has no attribute '_user_cache'

During handling of the above exception, another exception occurred:

Traceback (most recent call last):
  File "/home/python/.virtualenvs/py3_django/lib/python3.5/site-packages/django/db/backends/utils.py", line 65, in execute
    return self.cursor.execute(sql, params)
  File "/home/python/.virtualenvs/py3_django/lib/python3.5/site-packages/django/db/backends/mysql/base.py", line 101, in execute
    return self.cursor.execute(query, args)
  File "/home/python/.virtualenvs/py3_django/lib/python3.5/site-packages/pymysql/cursors.py", line 170, in execute
    result = self._query(query)
  File "/home/python/.virtualenvs/py3_django/lib/python3.5/site-packages/pymysql/cursors.py", line 328, in _query
    conn.query(q)
  File "/home/python/.virtualenvs/py3_django/lib/python3.5/site-packages/pymysql/connections.py", line 516, in query
    self._affected_rows = self._read_query_result(unbuffered=unbuffered)
  File "/home/python/.virtualenvs/py3_django/lib/python3.5/site-packages/pymysql/connections.py", line 727, in _read_query_result
    result.read()
  File "/home/python/.virtualenvs/py3_django/lib/python3.5/site-packages/pymysql/connections.py", line 1066, in read
    first_packet = self.connection._read_packet()
  File "/home/python/.virtualenvs/py3_django/lib/python3.5/site-packages/pymysql/connections.py", line 683, in _read_packet
    packet.check_error()
  File "/home/python/.virtualenvs/py3_django/lib/python3.5/site-packages/pymysql/protocol.py", line 220, in check_error
    err.raise_mysql_exception(self._data)
  File "/home/python/.virtualenvs/py3_django/lib/python3.5/site-packages/pymysql/err.py", line 109, in raise_mysql_exception
    raise errorclass(errno, errval)
pymysql.err.InternalError: (1054, "Unknown column 'users_user.email_active' in 'field list'")

The above exception was the direct cause of the following exception:

Traceback (most recent call last):
  File "/home/python/.virtualenvs/py3_django/lib/python3.5/site-packages/rest_framework/views.py", line 480, in dispatch
    response = handler(request, *args, **kwargs)
  File "/home/python/Desktop/meiduo/demo/demo/apps/oauth/views.py", line 54, in get
    token = jwt_token.generate(qq.user)
  File "/home/python/.virtualenvs/py3_django/lib/python3.5/site-packages/django/db/models/fields/related_descriptors.py", line 184, in __get__
    rel_obj = self.get_object(instance)
  File "/home/python/.virtualenvs/py3_django/lib/python3.5/site-packages/django/db/models/fields/related_descriptors.py", line 159, in get_object
    return qs.get(self.field.get_reverse_related_filter(instance))
  File "/home/python/.virtualenvs/py3_django/lib/python3.5/site-packages/django/db/models/query.py", line 373, in get
    num = len(clone)
  File "/home/python/.virtualenvs/py3_django/lib/python3.5/site-packages/django/db/models/query.py", line 232, in __len__
    self._fetch_all()
  File "/home/python/.virtualenvs/py3_django/lib/python3.5/site-packages/django/db/models/query.py", line 1102, in _fetch_all
    self._result_cache = list(self._iterable_class(self))
  File "/home/python/.virtualenvs/py3_django/lib/python3.5/site-packages/django/db/models/query.py", line 53, in __iter__
    results = compiler.execute_sql(chunked_fetch=self.chunked_fetch)
  File "/home/python/.virtualenvs/py3_django/lib/python3.5/site-packages/django/db/models/sql/compiler.py", line 876, in execute_sql
    cursor.execute(sql, params)
  File "/home/python/.virtualenvs/py3_django/lib/python3.5/site-packages/django/db/backends/utils.py", line 80, in execute
    return super(CursorDebugWrapper, self).execute(sql, params)
  File "/home/python/.virtualenvs/py3_django/lib/python3.5/site-packages/django/db/backends/utils.py", line 65, in execute
    return self.cursor.execute(sql, params)
  File "/home/python/.virtualenvs/py3_django/lib/python3.5/site-packages/django/db/utils.py", line 94, in __exit__
    six.reraise(dj_exc_type, dj_exc_value, traceback)
  File "/home/python/.virtualenvs/py3_django/lib/python3.5/site-packages/django/utils/six.py", line 685, in reraise
    raise value.with_traceback(tb)
  File "/home/python/.virtualenvs/py3_django/lib/python3.5/site-packages/django/db/backends/utils.py", line 65, in execute
    return self.cursor.execute(sql, params)
  File "/home/python/.virtualenvs/py3_django/lib/python3.5/site-packages/django/db/backends/mysql/base.py", line 101, in execute
    return self.cursor.execute(query, args)
  File "/home/python/.virtualenvs/py3_django/lib/python3.5/site-packages/pymysql/cursors.py", line 170, in execute
    result = self._query(query)
  File "/home/python/.virtualenvs/py3_django/lib/python3.5/site-packages/pymysql/cursors.py", line 328, in _query
    conn.query(q)
  File "/home/python/.virtualenvs/py3_django/lib/python3.5/site-packages/pymysql/connections.py", line 516, in query
    self._affected_rows = self._read_query_result(unbuffered=unbuffered)
  File "/home/python/.virtualenvs/py3_django/lib/python3.5/site-packages/pymysql/connections.py", line 727, in _read_query_result
    result.read()
  File "/home/python/.virtualenvs/py3_django/lib/python3.5/site-packages/pymysql/connections.py", line 1066, in read
    first_packet = self.connection._read_packet()
  File "/home/python/.virtualenvs/py3_django/lib/python3.5/site-packages/pymysql/connections.py", line 683, in _read_packet
    packet.check_error()
  File "/home/python/.virtualenvs/py3_django/lib/python3.5/site-packages/pymysql/protocol.py", line 220, in check_error
    err.raise_mysql_exception(self._data)
  File "/home/python/.virtualenvs/py3_django/lib/python3.5/site-packages/pymysql/err.py", line 109, in raise_mysql_exception
    raise errorclass(errno, errval)
django.db.utils.InternalError: (1054, "Unknown column 'users_user.email_active' in 'field list'")

During handling of the above exception, another exception occurred:

Traceback (most recent call last):
  File "/home/python/.virtualenvs/py3_django/lib/python3.5/site-packages/rest_framework/settings.py", line 183, in import_from_string
    module = import_module(module_path)
  File "/home/python/.virtualenvs/py3_django/lib/python3.5/importlib/__init__.py", line 126, in import_module
    return _bootstrap._gcd_import(name[level:], package, level)
  File "<frozen importlib._bootstrap>", line 986, in _gcd_import
  File "<frozen importlib._bootstrap>", line 969, in _find_and_load
  File "<frozen importlib._bootstrap>", line 944, in _find_and_load_unlocked
  File "<frozen importlib._bootstrap>", line 222, in _call_with_frames_removed
  File "<frozen importlib._bootstrap>", line 986, in _gcd_import
  File "<frozen importlib._bootstrap>", line 969, in _find_and_load
  File "<frozen importlib._bootstrap>", line 956, in _find_and_load_unlocked
ImportError: No module named 'utils'

During handling of the above exception, another exception occurred:

Traceback (most recent call last):
  File "/home/python/.virtualenvs/py3_django/lib/python3.5/site-packages/django/core/handlers/exception.py", line 41, in inner
    response = get_response(request)
  File "/home/python/.virtualenvs/py3_django/lib/python3.5/site-packages/django/core/handlers/base.py", line 187, in _get_response
    response = self.process_exception_by_middleware(e, request)
  File "/home/python/.virtualenvs/py3_django/lib/python3.5/site-packages/django/core/handlers/base.py", line 185, in _get_response
    response = wrapped_callback(request, *callback_args, **callback_kwargs)
  File "/home/python/.virtualenvs/py3_django/lib/python3.5/site-packages/django/views/decorators/csrf.py", line 58, in wrapped_view
    return view_func(*args, **kwargs)
  File "/home/python/.virtualenvs/py3_django/lib/python3.5/site-packages/django/views/generic/base.py", line 68, in view
    return self.dispatch(request, *args, **kwargs)
  File "/home/python/.virtualenvs/py3_django/lib/python3.5/site-packages/rest_framework/views.py", line 483, in dispatch
    response = self.handle_exception(exc)
  File "/home/python/.virtualenvs/py3_django/lib/python3.5/site-packages/rest_framework/views.py", line 437, in handle_exception
    exception_handler = self.get_exception_handler()
  File "/home/python/.virtualenvs/py3_django/lib/python3.5/site-packages/rest_framework/views.py", line 288, in get_exception_handler
    return self.settings.EXCEPTION_HANDLER
  File "/home/python/.virtualenvs/py3_django/lib/python3.5/site-packages/rest_framework/settings.py", line 227, in __getattr__
    val = perform_import(val, attr)
  File "/home/python/.virtualenvs/py3_django/lib/python3.5/site-packages/rest_framework/settings.py", line 170, in perform_import
    return import_from_string(val, setting_name)
  File "/home/python/.virtualenvs/py3_django/lib/python3.5/site-packages/rest_framework/settings.py", line 187, in import_from_string
    raise ImportError(msg)
ImportError: Could not import 'utils.exceptions.exception_handler' for API setting 'EXCEPTION_HANDLER'. ImportError: No module named 'utils'.
ERROR 2018-12-09 11:47:59,926 basehttp 124 "GET /oauth/qq/user/?code=410B4C12DDDDC879E9E83C3D2B25024B HTTP/1.1" 500 262643
ERROR 2018-12-09 11:48:19,154 qq_sdk 59 code=None msg=None
ERROR 2018-12-09 11:48:19,155 exception 135 Internal Server Error: /oauth/qq/user/
Traceback (most recent call last):
  File "/home/python/.virtualenvs/py3_django/lib/python3.5/site-packages/rest_framework/views.py", line 480, in dispatch
    response = handler(request, *args, **kwargs)
  File "/home/python/Desktop/meiduo/demo/demo/apps/oauth/views.py", line 37, in get
    token = oauthQQ.get_access_token(code)
  File "/home/python/Desktop/meiduo/demo/demo/utils/qq_sdk.py", line 60, in get_access_token
    raise Exception('获取access token失败')
Exception: 获取access token失败

During handling of the above exception, another exception occurred:

Traceback (most recent call last):
  File "/home/python/.virtualenvs/py3_django/lib/python3.5/site-packages/rest_framework/settings.py", line 183, in import_from_string
    module = import_module(module_path)
  File "/home/python/.virtualenvs/py3_django/lib/python3.5/importlib/__init__.py", line 126, in import_module
    return _bootstrap._gcd_import(name[level:], package, level)
  File "<frozen importlib._bootstrap>", line 986, in _gcd_import
  File "<frozen importlib._bootstrap>", line 969, in _find_and_load
  File "<frozen importlib._bootstrap>", line 944, in _find_and_load_unlocked
  File "<frozen importlib._bootstrap>", line 222, in _call_with_frames_removed
  File "<frozen importlib._bootstrap>", line 986, in _gcd_import
  File "<frozen importlib._bootstrap>", line 969, in _find_and_load
  File "<frozen importlib._bootstrap>", line 956, in _find_and_load_unlocked
ImportError: No module named 'utils'

During handling of the above exception, another exception occurred:

Traceback (most recent call last):
  File "/home/python/.virtualenvs/py3_django/lib/python3.5/site-packages/django/core/handlers/exception.py", line 41, in inner
    response = get_response(request)
  File "/home/python/.virtualenvs/py3_django/lib/python3.5/site-packages/django/core/handlers/base.py", line 187, in _get_response
    response = self.process_exception_by_middleware(e, request)
  File "/home/python/.virtualenvs/py3_django/lib/python3.5/site-packages/django/core/handlers/base.py", line 185, in _get_response
    response = wrapped_callback(request, *callback_args, **callback_kwargs)
  File "/home/python/.virtualenvs/py3_django/lib/python3.5/site-packages/django/views/decorators/csrf.py", line 58, in wrapped_view
    return view_func(*args, **kwargs)
  File "/home/python/.virtualenvs/py3_django/lib/python3.5/site-packages/django/views/generic/base.py", line 68, in view
    return self.dispatch(request, *args, **kwargs)
  File "/home/python/.virtualenvs/py3_django/lib/python3.5/site-packages/rest_framework/views.py", line 483, in dispatch
    response = self.handle_exception(exc)
  File "/home/python/.virtualenvs/py3_django/lib/python3.5/site-packages/rest_framework/views.py", line 437, in handle_exception
    exception_handler = self.get_exception_handler()
  File "/home/python/.virtualenvs/py3_django/lib/python3.5/site-packages/rest_framework/views.py", line 288, in get_exception_handler
    return self.settings.EXCEPTION_HANDLER
  File "/home/python/.virtualenvs/py3_django/lib/python3.5/site-packages/rest_framework/settings.py", line 227, in __getattr__
    val = perform_import(val, attr)
  File "/home/python/.virtualenvs/py3_django/lib/python3.5/site-packages/rest_framework/settings.py", line 170, in perform_import
    return import_from_string(val, setting_name)
  File "/home/python/.virtualenvs/py3_django/lib/python3.5/site-packages/rest_framework/settings.py", line 187, in import_from_string
    raise ImportError(msg)
ImportError: Could not import 'utils.exceptions.exception_handler' for API setting 'EXCEPTION_HANDLER'. ImportError: No module named 'utils'.
ERROR 2018-12-09 11:48:19,377 basehttp 124 "GET /oauth/qq/user/?code=410B4C12DDDDC879E9E83C3D2B25024B HTTP/1.1" 500 126934
WARNING 2018-12-09 11:48:20,449 base 152 Not Found: /favicon.ico
WARNING 2018-12-09 11:48:20,454 basehttp 124 "GET /favicon.ico HTTP/1.1" 404 3127
ERROR 2018-12-09 11:48:23,278 qq_sdk 59 code=None msg=None
ERROR 2018-12-09 11:48:23,279 exception 135 Internal Server Error: /oauth/qq/user/
Traceback (most recent call last):
  File "/home/python/.virtualenvs/py3_django/lib/python3.5/site-packages/rest_framework/views.py", line 480, in dispatch
    response = handler(request, *args, **kwargs)
  File "/home/python/Desktop/meiduo/demo/demo/apps/oauth/views.py", line 37, in get
    token = oauthQQ.get_access_token(code)
  File "/home/python/Desktop/meiduo/demo/demo/utils/qq_sdk.py", line 60, in get_access_token
    raise Exception('获取access token失败')
Exception: 获取access token失败

During handling of the above exception, another exception occurred:

Traceback (most recent call last):
  File "/home/python/.virtualenvs/py3_django/lib/python3.5/site-packages/rest_framework/settings.py", line 183, in import_from_string
    module = import_module(module_path)
  File "/home/python/.virtualenvs/py3_django/lib/python3.5/importlib/__init__.py", line 126, in import_module
    return _bootstrap._gcd_import(name[level:], package, level)
  File "<frozen importlib._bootstrap>", line 986, in _gcd_import
  File "<frozen importlib._bootstrap>", line 969, in _find_and_load
  File "<frozen importlib._bootstrap>", line 944, in _find_and_load_unlocked
  File "<frozen importlib._bootstrap>", line 222, in _call_with_frames_removed
  File "<frozen importlib._bootstrap>", line 986, in _gcd_import
  File "<frozen importlib._bootstrap>", line 969, in _find_and_load
  File "<frozen importlib._bootstrap>", line 956, in _find_and_load_unlocked
ImportError: No module named 'utils'

During handling of the above exception, another exception occurred:

Traceback (most recent call last):
  File "/home/python/.virtualenvs/py3_django/lib/python3.5/site-packages/django/core/handlers/exception.py", line 41, in inner
    response = get_response(request)
  File "/home/python/.virtualenvs/py3_django/lib/python3.5/site-packages/django/core/handlers/base.py", line 187, in _get_response
    response = self.process_exception_by_middleware(e, request)
  File "/home/python/.virtualenvs/py3_django/lib/python3.5/site-packages/django/core/handlers/base.py", line 185, in _get_response
    response = wrapped_callback(request, *callback_args, **callback_kwargs)
  File "/home/python/.virtualenvs/py3_django/lib/python3.5/site-packages/django/views/decorators/csrf.py", line 58, in wrapped_view
    return view_func(*args, **kwargs)
  File "/home/python/.virtualenvs/py3_django/lib/python3.5/site-packages/django/views/generic/base.py", line 68, in view
    return self.dispatch(request, *args, **kwargs)
  File "/home/python/.virtualenvs/py3_django/lib/python3.5/site-packages/rest_framework/views.py", line 483, in dispatch
    response = self.handle_exception(exc)
  File "/home/python/.virtualenvs/py3_django/lib/python3.5/site-packages/rest_framework/views.py", line 437, in handle_exception
    exception_handler = self.get_exception_handler()
  File "/home/python/.virtualenvs/py3_django/lib/python3.5/site-packages/rest_framework/views.py", line 288, in get_exception_handler
    return self.settings.EXCEPTION_HANDLER
  File "/home/python/.virtualenvs/py3_django/lib/python3.5/site-packages/rest_framework/settings.py", line 227, in __getattr__
    val = perform_import(val, attr)
  File "/home/python/.virtualenvs/py3_django/lib/python3.5/site-packages/rest_framework/settings.py", line 170, in perform_import
    return import_from_string(val, setting_name)
  File "/home/python/.virtualenvs/py3_django/lib/python3.5/site-packages/rest_framework/settings.py", line 187, in import_from_string
    raise ImportError(msg)
ImportError: Could not import 'utils.exceptions.exception_handler' for API setting 'EXCEPTION_HANDLER'. ImportError: No module named 'utils'.
ERROR 2018-12-09 11:48:23,450 basehttp 124 "GET /oauth/qq/user/?code=410B4C12DDDDC879E9E83C3D2B25024B HTTP/1.1" 500 126934
ERROR 2018-12-09 11:49:53,306 qq_sdk 59 code=None msg=None
ERROR 2018-12-09 11:49:53,307 exception 135 Internal Server Error: /oauth/qq/user/
Traceback (most recent call last):
  File "/home/python/.virtualenvs/py3_django/lib/python3.5/site-packages/rest_framework/views.py", line 480, in dispatch
    response = handler(request, *args, **kwargs)
  File "/home/python/Desktop/meiduo/demo/demo/apps/oauth/views.py", line 37, in get
    token = oauthQQ.get_access_token(code)
  File "/home/python/Desktop/meiduo/demo/demo/utils/qq_sdk.py", line 60, in get_access_token
    raise Exception('获取access token失败')
Exception: 获取access token失败

During handling of the above exception, another exception occurred:

Traceback (most recent call last):
  File "/home/python/.virtualenvs/py3_django/lib/python3.5/site-packages/rest_framework/settings.py", line 183, in import_from_string
    module = import_module(module_path)
  File "/home/python/.virtualenvs/py3_django/lib/python3.5/importlib/__init__.py", line 126, in import_module
    return _bootstrap._gcd_import(name[level:], package, level)
  File "<frozen importlib._bootstrap>", line 986, in _gcd_import
  File "<frozen importlib._bootstrap>", line 969, in _find_and_load
  File "<frozen importlib._bootstrap>", line 944, in _find_and_load_unlocked
  File "<frozen importlib._bootstrap>", line 222, in _call_with_frames_removed
  File "<frozen importlib._bootstrap>", line 986, in _gcd_import
  File "<frozen importlib._bootstrap>", line 969, in _find_and_load
  File "<frozen importlib._bootstrap>", line 956, in _find_and_load_unlocked
ImportError: No module named 'utils'

During handling of the above exception, another exception occurred:

Traceback (most recent call last):
  File "/home/python/.virtualenvs/py3_django/lib/python3.5/site-packages/django/core/handlers/exception.py", line 41, in inner
    response = get_response(request)
  File "/home/python/.virtualenvs/py3_django/lib/python3.5/site-packages/django/core/handlers/base.py", line 187, in _get_response
    response = self.process_exception_by_middleware(e, request)
  File "/home/python/.virtualenvs/py3_django/lib/python3.5/site-packages/django/core/handlers/base.py", line 185, in _get_response
    response = wrapped_callback(request, *callback_args, **callback_kwargs)
  File "/home/python/.virtualenvs/py3_django/lib/python3.5/site-packages/django/views/decorators/csrf.py", line 58, in wrapped_view
    return view_func(*args, **kwargs)
  File "/home/python/.virtualenvs/py3_django/lib/python3.5/site-packages/django/views/generic/base.py", line 68, in view
    return self.dispatch(request, *args, **kwargs)
  File "/home/python/.virtualenvs/py3_django/lib/python3.5/site-packages/rest_framework/views.py", line 483, in dispatch
    response = self.handle_exception(exc)
  File "/home/python/.virtualenvs/py3_django/lib/python3.5/site-packages/rest_framework/views.py", line 437, in handle_exception
    exception_handler = self.get_exception_handler()
  File "/home/python/.virtualenvs/py3_django/lib/python3.5/site-packages/rest_framework/views.py", line 288, in get_exception_handler
    return self.settings.EXCEPTION_HANDLER
  File "/home/python/.virtualenvs/py3_django/lib/python3.5/site-packages/rest_framework/settings.py", line 227, in __getattr__
    val = perform_import(val, attr)
  File "/home/python/.virtualenvs/py3_django/lib/python3.5/site-packages/rest_framework/settings.py", line 170, in perform_import
    return import_from_string(val, setting_name)
  File "/home/python/.virtualenvs/py3_django/lib/python3.5/site-packages/rest_framework/settings.py", line 187, in import_from_string
    raise ImportError(msg)
ImportError: Could not import 'utils.exceptions.exception_handler' for API setting 'EXCEPTION_HANDLER'. ImportError: No module named 'utils'.
ERROR 2018-12-09 11:49:53,686 basehttp 124 "GET /oauth/qq/user/?code=410B4C12DDDDC879E9E83C3D2B25024B HTTP/1.1" 500 127380
INFO 2018-12-09 11:50:35,676 basehttp 124 "OPTIONS /authorizations/ HTTP/1.1" 200 0
WARNING 2018-12-09 11:50:36,185 basehttp 124 "POST /authorizations/ HTTP/1.1" 400 67
INFO 2018-12-09 11:50:49,998 basehttp 124 "GET /oauth/qq/authorization/?next=/ HTTP/1.1" 200 195
ERROR 2018-12-09 11:51:01,089 exception 135 Internal Server Error: /oauth/qq/user/
Traceback (most recent call last):
  File "/home/python/.virtualenvs/py3_django/lib/python3.5/site-packages/django/db/models/fields/related_descriptors.py", line 178, in __get__
    rel_obj = getattr(instance, self.cache_name)
AttributeError: 'OauthQQ' object has no attribute '_user_cache'

During handling of the above exception, another exception occurred:

Traceback (most recent call last):
  File "/home/python/.virtualenvs/py3_django/lib/python3.5/site-packages/django/db/backends/utils.py", line 65, in execute
    return self.cursor.execute(sql, params)
  File "/home/python/.virtualenvs/py3_django/lib/python3.5/site-packages/django/db/backends/mysql/base.py", line 101, in execute
    return self.cursor.execute(query, args)
  File "/home/python/.virtualenvs/py3_django/lib/python3.5/site-packages/pymysql/cursors.py", line 170, in execute
    result = self._query(query)
  File "/home/python/.virtualenvs/py3_django/lib/python3.5/site-packages/pymysql/cursors.py", line 328, in _query
    conn.query(q)
  File "/home/python/.virtualenvs/py3_django/lib/python3.5/site-packages/pymysql/connections.py", line 516, in query
    self._affected_rows = self._read_query_result(unbuffered=unbuffered)
  File "/home/python/.virtualenvs/py3_django/lib/python3.5/site-packages/pymysql/connections.py", line 727, in _read_query_result
    result.read()
  File "/home/python/.virtualenvs/py3_django/lib/python3.5/site-packages/pymysql/connections.py", line 1066, in read
    first_packet = self.connection._read_packet()
  File "/home/python/.virtualenvs/py3_django/lib/python3.5/site-packages/pymysql/connections.py", line 683, in _read_packet
    packet.check_error()
  File "/home/python/.virtualenvs/py3_django/lib/python3.5/site-packages/pymysql/protocol.py", line 220, in check_error
    err.raise_mysql_exception(self._data)
  File "/home/python/.virtualenvs/py3_django/lib/python3.5/site-packages/pymysql/err.py", line 109, in raise_mysql_exception
    raise errorclass(errno, errval)
pymysql.err.InternalError: (1054, "Unknown column 'users_user.email_active' in 'field list'")

The above exception was the direct cause of the following exception:

Traceback (most recent call last):
  File "/home/python/.virtualenvs/py3_django/lib/python3.5/site-packages/rest_framework/views.py", line 480, in dispatch
    response = handler(request, *args, **kwargs)
  File "/home/python/Desktop/meiduo/demo/demo/apps/oauth/views.py", line 54, in get
    token = jwt_token.generate(qq.user)
  File "/home/python/.virtualenvs/py3_django/lib/python3.5/site-packages/django/db/models/fields/related_descriptors.py", line 184, in __get__
    rel_obj = self.get_object(instance)
  File "/home/python/.virtualenvs/py3_django/lib/python3.5/site-packages/django/db/models/fields/related_descriptors.py", line 159, in get_object
    return qs.get(self.field.get_reverse_related_filter(instance))
  File "/home/python/.virtualenvs/py3_django/lib/python3.5/site-packages/django/db/models/query.py", line 373, in get
    num = len(clone)
  File "/home/python/.virtualenvs/py3_django/lib/python3.5/site-packages/django/db/models/query.py", line 232, in __len__
    self._fetch_all()
  File "/home/python/.virtualenvs/py3_django/lib/python3.5/site-packages/django/db/models/query.py", line 1102, in _fetch_all
    self._result_cache = list(self._iterable_class(self))
  File "/home/python/.virtualenvs/py3_django/lib/python3.5/site-packages/django/db/models/query.py", line 53, in __iter__
    results = compiler.execute_sql(chunked_fetch=self.chunked_fetch)
  File "/home/python/.virtualenvs/py3_django/lib/python3.5/site-packages/django/db/models/sql/compiler.py", line 876, in execute_sql
    cursor.execute(sql, params)
  File "/home/python/.virtualenvs/py3_django/lib/python3.5/site-packages/django/db/backends/utils.py", line 80, in execute
    return super(CursorDebugWrapper, self).execute(sql, params)
  File "/home/python/.virtualenvs/py3_django/lib/python3.5/site-packages/django/db/backends/utils.py", line 65, in execute
    return self.cursor.execute(sql, params)
  File "/home/python/.virtualenvs/py3_django/lib/python3.5/site-packages/django/db/utils.py", line 94, in __exit__
    six.reraise(dj_exc_type, dj_exc_value, traceback)
  File "/home/python/.virtualenvs/py3_django/lib/python3.5/site-packages/django/utils/six.py", line 685, in reraise
    raise value.with_traceback(tb)
  File "/home/python/.virtualenvs/py3_django/lib/python3.5/site-packages/django/db/backends/utils.py", line 65, in execute
    return self.cursor.execute(sql, params)
  File "/home/python/.virtualenvs/py3_django/lib/python3.5/site-packages/django/db/backends/mysql/base.py", line 101, in execute
    return self.cursor.execute(query, args)
  File "/home/python/.virtualenvs/py3_django/lib/python3.5/site-packages/pymysql/cursors.py", line 170, in execute
    result = self._query(query)
  File "/home/python/.virtualenvs/py3_django/lib/python3.5/site-packages/pymysql/cursors.py", line 328, in _query
    conn.query(q)
  File "/home/python/.virtualenvs/py3_django/lib/python3.5/site-packages/pymysql/connections.py", line 516, in query
    self._affected_rows = self._read_query_result(unbuffered=unbuffered)
  File "/home/python/.virtualenvs/py3_django/lib/python3.5/site-packages/pymysql/connections.py", line 727, in _read_query_result
    result.read()
  File "/home/python/.virtualenvs/py3_django/lib/python3.5/site-packages/pymysql/connections.py", line 1066, in read
    first_packet = self.connection._read_packet()
  File "/home/python/.virtualenvs/py3_django/lib/python3.5/site-packages/pymysql/connections.py", line 683, in _read_packet
    packet.check_error()
  File "/home/python/.virtualenvs/py3_django/lib/python3.5/site-packages/pymysql/protocol.py", line 220, in check_error
    err.raise_mysql_exception(self._data)
  File "/home/python/.virtualenvs/py3_django/lib/python3.5/site-packages/pymysql/err.py", line 109, in raise_mysql_exception
    raise errorclass(errno, errval)
django.db.utils.InternalError: (1054, "Unknown column 'users_user.email_active' in 'field list'")

During handling of the above exception, another exception occurred:

Traceback (most recent call last):
  File "/home/python/.virtualenvs/py3_django/lib/python3.5/site-packages/rest_framework/settings.py", line 183, in import_from_string
    module = import_module(module_path)
  File "/home/python/.virtualenvs/py3_django/lib/python3.5/importlib/__init__.py", line 126, in import_module
    return _bootstrap._gcd_import(name[level:], package, level)
  File "<frozen importlib._bootstrap>", line 986, in _gcd_import
  File "<frozen importlib._bootstrap>", line 969, in _find_and_load
  File "<frozen importlib._bootstrap>", line 944, in _find_and_load_unlocked
  File "<frozen importlib._bootstrap>", line 222, in _call_with_frames_removed
  File "<frozen importlib._bootstrap>", line 986, in _gcd_import
  File "<frozen importlib._bootstrap>", line 969, in _find_and_load
  File "<frozen importlib._bootstrap>", line 956, in _find_and_load_unlocked
ImportError: No module named 'utils'

During handling of the above exception, another exception occurred:

Traceback (most recent call last):
  File "/home/python/.virtualenvs/py3_django/lib/python3.5/site-packages/django/core/handlers/exception.py", line 41, in inner
    response = get_response(request)
  File "/home/python/.virtualenvs/py3_django/lib/python3.5/site-packages/django/core/handlers/base.py", line 187, in _get_response
    response = self.process_exception_by_middleware(e, request)
  File "/home/python/.virtualenvs/py3_django/lib/python3.5/site-packages/django/core/handlers/base.py", line 185, in _get_response
    response = wrapped_callback(request, *callback_args, **callback_kwargs)
  File "/home/python/.virtualenvs/py3_django/lib/python3.5/site-packages/django/views/decorators/csrf.py", line 58, in wrapped_view
    return view_func(*args, **kwargs)
  File "/home/python/.virtualenvs/py3_django/lib/python3.5/site-packages/django/views/generic/base.py", line 68, in view
    return self.dispatch(request, *args, **kwargs)
  File "/home/python/.virtualenvs/py3_django/lib/python3.5/site-packages/rest_framework/views.py", line 483, in dispatch
    response = self.handle_exception(exc)
  File "/home/python/.virtualenvs/py3_django/lib/python3.5/site-packages/rest_framework/views.py", line 437, in handle_exception
    exception_handler = self.get_exception_handler()
  File "/home/python/.virtualenvs/py3_django/lib/python3.5/site-packages/rest_framework/views.py", line 288, in get_exception_handler
    return self.settings.EXCEPTION_HANDLER
  File "/home/python/.virtualenvs/py3_django/lib/python3.5/site-packages/rest_framework/settings.py", line 227, in __getattr__
    val = perform_import(val, attr)
  File "/home/python/.virtualenvs/py3_django/lib/python3.5/site-packages/rest_framework/settings.py", line 170, in perform_import
    return import_from_string(val, setting_name)
  File "/home/python/.virtualenvs/py3_django/lib/python3.5/site-packages/rest_framework/settings.py", line 187, in import_from_string
    raise ImportError(msg)
ImportError: Could not import 'utils.exceptions.exception_handler' for API setting 'EXCEPTION_HANDLER'. ImportError: No module named 'utils'.
ERROR 2018-12-09 11:51:01,648 basehttp 124 "GET /oauth/qq/user/?code=46B3146C0C8405C6E66204F4C3A87322 HTTP/1.1" 500 262902
ERROR 2018-12-09 11:52:07,966 qq_sdk 59 code=None msg=None
ERROR 2018-12-09 11:52:07,968 exception 135 Internal Server Error: /oauth/qq/user/
Traceback (most recent call last):
  File "/home/python/.virtualenvs/py3_django/lib/python3.5/site-packages/rest_framework/views.py", line 480, in dispatch
    response = handler(request, *args, **kwargs)
  File "/home/python/Desktop/meiduo/demo/demo/apps/oauth/views.py", line 37, in get
    token = oauthQQ.get_access_token(code)
  File "/home/python/Desktop/meiduo/demo/demo/utils/qq_sdk.py", line 60, in get_access_token
    raise Exception('获取access token失败')
Exception: 获取access token失败

During handling of the above exception, another exception occurred:

Traceback (most recent call last):
  File "/home/python/.virtualenvs/py3_django/lib/python3.5/site-packages/rest_framework/settings.py", line 183, in import_from_string
    module = import_module(module_path)
  File "/home/python/.virtualenvs/py3_django/lib/python3.5/importlib/__init__.py", line 126, in import_module
    return _bootstrap._gcd_import(name[level:], package, level)
  File "<frozen importlib._bootstrap>", line 986, in _gcd_import
  File "<frozen importlib._bootstrap>", line 969, in _find_and_load
  File "<frozen importlib._bootstrap>", line 944, in _find_and_load_unlocked
  File "<frozen importlib._bootstrap>", line 222, in _call_with_frames_removed
  File "<frozen importlib._bootstrap>", line 986, in _gcd_import
  File "<frozen importlib._bootstrap>", line 969, in _find_and_load
  File "<frozen importlib._bootstrap>", line 956, in _find_and_load_unlocked
ImportError: No module named 'utils'

During handling of the above exception, another exception occurred:

Traceback (most recent call last):
  File "/home/python/.virtualenvs/py3_django/lib/python3.5/site-packages/django/core/handlers/exception.py", line 41, in inner
    response = get_response(request)
  File "/home/python/.virtualenvs/py3_django/lib/python3.5/site-packages/django/core/handlers/base.py", line 187, in _get_response
    response = self.process_exception_by_middleware(e, request)
  File "/home/python/.virtualenvs/py3_django/lib/python3.5/site-packages/django/core/handlers/base.py", line 185, in _get_response
    response = wrapped_callback(request, *callback_args, **callback_kwargs)
  File "/home/python/.virtualenvs/py3_django/lib/python3.5/site-packages/django/views/decorators/csrf.py", line 58, in wrapped_view
    return view_func(*args, **kwargs)
  File "/home/python/.virtualenvs/py3_django/lib/python3.5/site-packages/django/views/generic/base.py", line 68, in view
    return self.dispatch(request, *args, **kwargs)
  File "/home/python/.virtualenvs/py3_django/lib/python3.5/site-packages/rest_framework/views.py", line 483, in dispatch
    response = self.handle_exception(exc)
  File "/home/python/.virtualenvs/py3_django/lib/python3.5/site-packages/rest_framework/views.py", line 437, in handle_exception
    exception_handler = self.get_exception_handler()
  File "/home/python/.virtualenvs/py3_django/lib/python3.5/site-packages/rest_framework/views.py", line 288, in get_exception_handler
    return self.settings.EXCEPTION_HANDLER
  File "/home/python/.virtualenvs/py3_django/lib/python3.5/site-packages/rest_framework/settings.py", line 227, in __getattr__
    val = perform_import(val, attr)
  File "/home/python/.virtualenvs/py3_django/lib/python3.5/site-packages/rest_framework/settings.py", line 170, in perform_import
    return import_from_string(val, setting_name)
  File "/home/python/.virtualenvs/py3_django/lib/python3.5/site-packages/rest_framework/settings.py", line 187, in import_from_string
    raise ImportError(msg)
ImportError: Could not import 'utils.exceptions.exception_handler' for API setting 'EXCEPTION_HANDLER'. ImportError: No module named 'utils'.
ERROR 2018-12-09 11:52:08,106 basehttp 124 "GET /oauth/qq/user/?code=46B3146C0C8405C6E66204F4C3A87322 HTTP/1.1" 500 127380
INFO 2018-12-09 11:52:18,258 basehttp 124 "GET /oauth/qq/authorization/?next=/ HTTP/1.1" 200 195
ERROR 2018-12-09 11:52:32,161 exception 135 Internal Server Error: /oauth/qq/user/
Traceback (most recent call last):
  File "/home/python/.virtualenvs/py3_django/lib/python3.5/site-packages/django/db/models/fields/related_descriptors.py", line 178, in __get__
    rel_obj = getattr(instance, self.cache_name)
AttributeError: 'OauthQQ' object has no attribute '_user_cache'

During handling of the above exception, another exception occurred:

Traceback (most recent call last):
  File "/home/python/.virtualenvs/py3_django/lib/python3.5/site-packages/django/db/backends/utils.py", line 65, in execute
    return self.cursor.execute(sql, params)
  File "/home/python/.virtualenvs/py3_django/lib/python3.5/site-packages/django/db/backends/mysql/base.py", line 101, in execute
    return self.cursor.execute(query, args)
  File "/home/python/.virtualenvs/py3_django/lib/python3.5/site-packages/pymysql/cursors.py", line 170, in execute
    result = self._query(query)
  File "/home/python/.virtualenvs/py3_django/lib/python3.5/site-packages/pymysql/cursors.py", line 328, in _query
    conn.query(q)
  File "/home/python/.virtualenvs/py3_django/lib/python3.5/site-packages/pymysql/connections.py", line 516, in query
    self._affected_rows = self._read_query_result(unbuffered=unbuffered)
  File "/home/python/.virtualenvs/py3_django/lib/python3.5/site-packages/pymysql/connections.py", line 727, in _read_query_result
    result.read()
  File "/home/python/.virtualenvs/py3_django/lib/python3.5/site-packages/pymysql/connections.py", line 1066, in read
    first_packet = self.connection._read_packet()
  File "/home/python/.virtualenvs/py3_django/lib/python3.5/site-packages/pymysql/connections.py", line 683, in _read_packet
    packet.check_error()
  File "/home/python/.virtualenvs/py3_django/lib/python3.5/site-packages/pymysql/protocol.py", line 220, in check_error
    err.raise_mysql_exception(self._data)
  File "/home/python/.virtualenvs/py3_django/lib/python3.5/site-packages/pymysql/err.py", line 109, in raise_mysql_exception
    raise errorclass(errno, errval)
pymysql.err.InternalError: (1054, "Unknown column 'users_user.email_active' in 'field list'")

The above exception was the direct cause of the following exception:

Traceback (most recent call last):
  File "/home/python/.virtualenvs/py3_django/lib/python3.5/site-packages/rest_framework/views.py", line 480, in dispatch
    response = handler(request, *args, **kwargs)
  File "/home/python/Desktop/meiduo/demo/demo/apps/oauth/views.py", line 54, in get
    token = jwt_token.generate(qq.user)
  File "/home/python/.virtualenvs/py3_django/lib/python3.5/site-packages/django/db/models/fields/related_descriptors.py", line 184, in __get__
    rel_obj = self.get_object(instance)
  File "/home/python/.virtualenvs/py3_django/lib/python3.5/site-packages/django/db/models/fields/related_descriptors.py", line 159, in get_object
    return qs.get(self.field.get_reverse_related_filter(instance))
  File "/home/python/.virtualenvs/py3_django/lib/python3.5/site-packages/django/db/models/query.py", line 373, in get
    num = len(clone)
  File "/home/python/.virtualenvs/py3_django/lib/python3.5/site-packages/django/db/models/query.py", line 232, in __len__
    self._fetch_all()
  File "/home/python/.virtualenvs/py3_django/lib/python3.5/site-packages/django/db/models/query.py", line 1102, in _fetch_all
    self._result_cache = list(self._iterable_class(self))
  File "/home/python/.virtualenvs/py3_django/lib/python3.5/site-packages/django/db/models/query.py", line 53, in __iter__
    results = compiler.execute_sql(chunked_fetch=self.chunked_fetch)
  File "/home/python/.virtualenvs/py3_django/lib/python3.5/site-packages/django/db/models/sql/compiler.py", line 876, in execute_sql
    cursor.execute(sql, params)
  File "/home/python/.virtualenvs/py3_django/lib/python3.5/site-packages/django/db/backends/utils.py", line 80, in execute
    return super(CursorDebugWrapper, self).execute(sql, params)
  File "/home/python/.virtualenvs/py3_django/lib/python3.5/site-packages/django/db/backends/utils.py", line 65, in execute
    return self.cursor.execute(sql, params)
  File "/home/python/.virtualenvs/py3_django/lib/python3.5/site-packages/django/db/utils.py", line 94, in __exit__
    six.reraise(dj_exc_type, dj_exc_value, traceback)
  File "/home/python/.virtualenvs/py3_django/lib/python3.5/site-packages/django/utils/six.py", line 685, in reraise
    raise value.with_traceback(tb)
  File "/home/python/.virtualenvs/py3_django/lib/python3.5/site-packages/django/db/backends/utils.py", line 65, in execute
    return self.cursor.execute(sql, params)
  File "/home/python/.virtualenvs/py3_django/lib/python3.5/site-packages/django/db/backends/mysql/base.py", line 101, in execute
    return self.cursor.execute(query, args)
  File "/home/python/.virtualenvs/py3_django/lib/python3.5/site-packages/pymysql/cursors.py", line 170, in execute
    result = self._query(query)
  File "/home/python/.virtualenvs/py3_django/lib/python3.5/site-packages/pymysql/cursors.py", line 328, in _query
    conn.query(q)
  File "/home/python/.virtualenvs/py3_django/lib/python3.5/site-packages/pymysql/connections.py", line 516, in query
    self._affected_rows = self._read_query_result(unbuffered=unbuffered)
  File "/home/python/.virtualenvs/py3_django/lib/python3.5/site-packages/pymysql/connections.py", line 727, in _read_query_result
    result.read()
  File "/home/python/.virtualenvs/py3_django/lib/python3.5/site-packages/pymysql/connections.py", line 1066, in read
    first_packet = self.connection._read_packet()
  File "/home/python/.virtualenvs/py3_django/lib/python3.5/site-packages/pymysql/connections.py", line 683, in _read_packet
    packet.check_error()
  File "/home/python/.virtualenvs/py3_django/lib/python3.5/site-packages/pymysql/protocol.py", line 220, in check_error
    err.raise_mysql_exception(self._data)
  File "/home/python/.virtualenvs/py3_django/lib/python3.5/site-packages/pymysql/err.py", line 109, in raise_mysql_exception
    raise errorclass(errno, errval)
django.db.utils.InternalError: (1054, "Unknown column 'users_user.email_active' in 'field list'")

During handling of the above exception, another exception occurred:

Traceback (most recent call last):
  File "/home/python/.virtualenvs/py3_django/lib/python3.5/site-packages/rest_framework/settings.py", line 183, in import_from_string
    module = import_module(module_path)
  File "/home/python/.virtualenvs/py3_django/lib/python3.5/importlib/__init__.py", line 126, in import_module
    return _bootstrap._gcd_import(name[level:], package, level)
  File "<frozen importlib._bootstrap>", line 986, in _gcd_import
  File "<frozen importlib._bootstrap>", line 969, in _find_and_load
  File "<frozen importlib._bootstrap>", line 944, in _find_and_load_unlocked
  File "<frozen importlib._bootstrap>", line 222, in _call_with_frames_removed
  File "<frozen importlib._bootstrap>", line 986, in _gcd_import
  File "<frozen importlib._bootstrap>", line 969, in _find_and_load
  File "<frozen importlib._bootstrap>", line 956, in _find_and_load_unlocked
ImportError: No module named 'utils'

During handling of the above exception, another exception occurred:

Traceback (most recent call last):
  File "/home/python/.virtualenvs/py3_django/lib/python3.5/site-packages/django/core/handlers/exception.py", line 41, in inner
    response = get_response(request)
  File "/home/python/.virtualenvs/py3_django/lib/python3.5/site-packages/django/core/handlers/base.py", line 187, in _get_response
    response = self.process_exception_by_middleware(e, request)
  File "/home/python/.virtualenvs/py3_django/lib/python3.5/site-packages/django/core/handlers/base.py", line 185, in _get_response
    response = wrapped_callback(request, *callback_args, **callback_kwargs)
  File "/home/python/.virtualenvs/py3_django/lib/python3.5/site-packages/django/views/decorators/csrf.py", line 58, in wrapped_view
    return view_func(*args, **kwargs)
  File "/home/python/.virtualenvs/py3_django/lib/python3.5/site-packages/django/views/generic/base.py", line 68, in view
    return self.dispatch(request, *args, **kwargs)
  File "/home/python/.virtualenvs/py3_django/lib/python3.5/site-packages/rest_framework/views.py", line 483, in dispatch
    response = self.handle_exception(exc)
  File "/home/python/.virtualenvs/py3_django/lib/python3.5/site-packages/rest_framework/views.py", line 437, in handle_exception
    exception_handler = self.get_exception_handler()
  File "/home/python/.virtualenvs/py3_django/lib/python3.5/site-packages/rest_framework/views.py", line 288, in get_exception_handler
    return self.settings.EXCEPTION_HANDLER
  File "/home/python/.virtualenvs/py3_django/lib/python3.5/site-packages/rest_framework/settings.py", line 227, in __getattr__
    val = perform_import(val, attr)
  File "/home/python/.virtualenvs/py3_django/lib/python3.5/site-packages/rest_framework/settings.py", line 170, in perform_import
    return import_from_string(val, setting_name)
  File "/home/python/.virtualenvs/py3_django/lib/python3.5/site-packages/rest_framework/settings.py", line 187, in import_from_string
    raise ImportError(msg)
ImportError: Could not import 'utils.exceptions.exception_handler' for API setting 'EXCEPTION_HANDLER'. ImportError: No module named 'utils'.
ERROR 2018-12-09 11:52:32,426 basehttp 124 "GET /oauth/qq/user/?code=BB3933378D190CF63D01C90BCD35C9FF HTTP/1.1" 500 262889
INFO 2018-12-09 11:53:53,869 basehttp 124 "GET /oauth/qq/authorization/?next=/ HTTP/1.1" 200 195
ERROR 2018-12-09 11:54:08,433 exception 135 Internal Server Error: /oauth/qq/user/
Traceback (most recent call last):
  File "/home/python/.virtualenvs/py3_django/lib/python3.5/site-packages/django/db/models/fields/related_descriptors.py", line 178, in __get__
    rel_obj = getattr(instance, self.cache_name)
AttributeError: 'OauthQQ' object has no attribute '_user_cache'

During handling of the above exception, another exception occurred:

Traceback (most recent call last):
  File "/home/python/.virtualenvs/py3_django/lib/python3.5/site-packages/django/db/backends/utils.py", line 65, in execute
    return self.cursor.execute(sql, params)
  File "/home/python/.virtualenvs/py3_django/lib/python3.5/site-packages/django/db/backends/mysql/base.py", line 101, in execute
    return self.cursor.execute(query, args)
  File "/home/python/.virtualenvs/py3_django/lib/python3.5/site-packages/pymysql/cursors.py", line 170, in execute
    result = self._query(query)
  File "/home/python/.virtualenvs/py3_django/lib/python3.5/site-packages/pymysql/cursors.py", line 328, in _query
    conn.query(q)
  File "/home/python/.virtualenvs/py3_django/lib/python3.5/site-packages/pymysql/connections.py", line 516, in query
    self._affected_rows = self._read_query_result(unbuffered=unbuffered)
  File "/home/python/.virtualenvs/py3_django/lib/python3.5/site-packages/pymysql/connections.py", line 727, in _read_query_result
    result.read()
  File "/home/python/.virtualenvs/py3_django/lib/python3.5/site-packages/pymysql/connections.py", line 1066, in read
    first_packet = self.connection._read_packet()
  File "/home/python/.virtualenvs/py3_django/lib/python3.5/site-packages/pymysql/connections.py", line 683, in _read_packet
    packet.check_error()
  File "/home/python/.virtualenvs/py3_django/lib/python3.5/site-packages/pymysql/protocol.py", line 220, in check_error
    err.raise_mysql_exception(self._data)
  File "/home/python/.virtualenvs/py3_django/lib/python3.5/site-packages/pymysql/err.py", line 109, in raise_mysql_exception
    raise errorclass(errno, errval)
pymysql.err.InternalError: (1054, "Unknown column 'users_user.email_active' in 'field list'")

The above exception was the direct cause of the following exception:

Traceback (most recent call last):
  File "/home/python/.virtualenvs/py3_django/lib/python3.5/site-packages/rest_framework/views.py", line 480, in dispatch
    response = handler(request, *args, **kwargs)
  File "/home/python/Desktop/meiduo/demo/demo/apps/oauth/views.py", line 54, in get
    token = jwt_token.generate(qq.user)
  File "/home/python/.virtualenvs/py3_django/lib/python3.5/site-packages/django/db/models/fields/related_descriptors.py", line 184, in __get__
    rel_obj = self.get_object(instance)
  File "/home/python/.virtualenvs/py3_django/lib/python3.5/site-packages/django/db/models/fields/related_descriptors.py", line 159, in get_object
    return qs.get(self.field.get_reverse_related_filter(instance))
  File "/home/python/.virtualenvs/py3_django/lib/python3.5/site-packages/django/db/models/query.py", line 373, in get
    num = len(clone)
  File "/home/python/.virtualenvs/py3_django/lib/python3.5/site-packages/django/db/models/query.py", line 232, in __len__
    self._fetch_all()
  File "/home/python/.virtualenvs/py3_django/lib/python3.5/site-packages/django/db/models/query.py", line 1102, in _fetch_all
    self._result_cache = list(self._iterable_class(self))
  File "/home/python/.virtualenvs/py3_django/lib/python3.5/site-packages/django/db/models/query.py", line 53, in __iter__
    results = compiler.execute_sql(chunked_fetch=self.chunked_fetch)
  File "/home/python/.virtualenvs/py3_django/lib/python3.5/site-packages/django/db/models/sql/compiler.py", line 876, in execute_sql
    cursor.execute(sql, params)
  File "/home/python/.virtualenvs/py3_django/lib/python3.5/site-packages/django/db/backends/utils.py", line 80, in execute
    return super(CursorDebugWrapper, self).execute(sql, params)
  File "/home/python/.virtualenvs/py3_django/lib/python3.5/site-packages/django/db/backends/utils.py", line 65, in execute
    return self.cursor.execute(sql, params)
  File "/home/python/.virtualenvs/py3_django/lib/python3.5/site-packages/django/db/utils.py", line 94, in __exit__
    six.reraise(dj_exc_type, dj_exc_value, traceback)
  File "/home/python/.virtualenvs/py3_django/lib/python3.5/site-packages/django/utils/six.py", line 685, in reraise
    raise value.with_traceback(tb)
  File "/home/python/.virtualenvs/py3_django/lib/python3.5/site-packages/django/db/backends/utils.py", line 65, in execute
    return self.cursor.execute(sql, params)
  File "/home/python/.virtualenvs/py3_django/lib/python3.5/site-packages/django/db/backends/mysql/base.py", line 101, in execute
    return self.cursor.execute(query, args)
  File "/home/python/.virtualenvs/py3_django/lib/python3.5/site-packages/pymysql/cursors.py", line 170, in execute
    result = self._query(query)
  File "/home/python/.virtualenvs/py3_django/lib/python3.5/site-packages/pymysql/cursors.py", line 328, in _query
    conn.query(q)
  File "/home/python/.virtualenvs/py3_django/lib/python3.5/site-packages/pymysql/connections.py", line 516, in query
    self._affected_rows = self._read_query_result(unbuffered=unbuffered)
  File "/home/python/.virtualenvs/py3_django/lib/python3.5/site-packages/pymysql/connections.py", line 727, in _read_query_result
    result.read()
  File "/home/python/.virtualenvs/py3_django/lib/python3.5/site-packages/pymysql/connections.py", line 1066, in read
    first_packet = self.connection._read_packet()
  File "/home/python/.virtualenvs/py3_django/lib/python3.5/site-packages/pymysql/connections.py", line 683, in _read_packet
    packet.check_error()
  File "/home/python/.virtualenvs/py3_django/lib/python3.5/site-packages/pymysql/protocol.py", line 220, in check_error
    err.raise_mysql_exception(self._data)
  File "/home/python/.virtualenvs/py3_django/lib/python3.5/site-packages/pymysql/err.py", line 109, in raise_mysql_exception
    raise errorclass(errno, errval)
django.db.utils.InternalError: (1054, "Unknown column 'users_user.email_active' in 'field list'")

During handling of the above exception, another exception occurred:

Traceback (most recent call last):
  File "/home/python/.virtualenvs/py3_django/lib/python3.5/site-packages/rest_framework/settings.py", line 183, in import_from_string
    module = import_module(module_path)
  File "/home/python/.virtualenvs/py3_django/lib/python3.5/importlib/__init__.py", line 126, in import_module
    return _bootstrap._gcd_import(name[level:], package, level)
  File "<frozen importlib._bootstrap>", line 986, in _gcd_import
  File "<frozen importlib._bootstrap>", line 969, in _find_and_load
  File "<frozen importlib._bootstrap>", line 944, in _find_and_load_unlocked
  File "<frozen importlib._bootstrap>", line 222, in _call_with_frames_removed
  File "<frozen importlib._bootstrap>", line 986, in _gcd_import
  File "<frozen importlib._bootstrap>", line 969, in _find_and_load
  File "<frozen importlib._bootstrap>", line 956, in _find_and_load_unlocked
ImportError: No module named 'utils'

During handling of the above exception, another exception occurred:

Traceback (most recent call last):
  File "/home/python/.virtualenvs/py3_django/lib/python3.5/site-packages/django/core/handlers/exception.py", line 41, in inner
    response = get_response(request)
  File "/home/python/.virtualenvs/py3_django/lib/python3.5/site-packages/django/core/handlers/base.py", line 187, in _get_response
    response = self.process_exception_by_middleware(e, request)
  File "/home/python/.virtualenvs/py3_django/lib/python3.5/site-packages/django/core/handlers/base.py", line 185, in _get_response
    response = wrapped_callback(request, *callback_args, **callback_kwargs)
  File "/home/python/.virtualenvs/py3_django/lib/python3.5/site-packages/django/views/decorators/csrf.py", line 58, in wrapped_view
    return view_func(*args, **kwargs)
  File "/home/python/.virtualenvs/py3_django/lib/python3.5/site-packages/django/views/generic/base.py", line 68, in view
    return self.dispatch(request, *args, **kwargs)
  File "/home/python/.virtualenvs/py3_django/lib/python3.5/site-packages/rest_framework/views.py", line 483, in dispatch
    response = self.handle_exception(exc)
  File "/home/python/.virtualenvs/py3_django/lib/python3.5/site-packages/rest_framework/views.py", line 437, in handle_exception
    exception_handler = self.get_exception_handler()
  File "/home/python/.virtualenvs/py3_django/lib/python3.5/site-packages/rest_framework/views.py", line 288, in get_exception_handler
    return self.settings.EXCEPTION_HANDLER
  File "/home/python/.virtualenvs/py3_django/lib/python3.5/site-packages/rest_framework/settings.py", line 227, in __getattr__
    val = perform_import(val, attr)
  File "/home/python/.virtualenvs/py3_django/lib/python3.5/site-packages/rest_framework/settings.py", line 170, in perform_import
    return import_from_string(val, setting_name)
  File "/home/python/.virtualenvs/py3_django/lib/python3.5/site-packages/rest_framework/settings.py", line 187, in import_from_string
    raise ImportError(msg)
ImportError: Could not import 'utils.exceptions.exception_handler' for API setting 'EXCEPTION_HANDLER'. ImportError: No module named 'utils'.
ERROR 2018-12-09 11:54:08,925 basehttp 124 "GET /oauth/qq/user/?code=F136EDA34CCD51BBB5DE1095C4693819 HTTP/1.1" 500 262888
INFO 2018-12-09 11:58:22,845 basehttp 124 "GET /mobiles/18731217902/count/ HTTP/1.1" 200 34
INFO 2018-12-09 11:58:22,893 basehttp 124 "GET /mobiles/18731217902/count/ HTTP/1.1" 200 34
INFO 2018-12-09 11:58:23,625 basehttp 124 "GET /sms_code/18731217902/ HTTP/1.1" 200 16
INFO 2018-12-09 11:59:09,529 basehttp 124 "GET /mobiles/18731217902/count/ HTTP/1.1" 200 34
INFO 2018-12-09 11:59:12,318 basehttp 124 "GET /mobiles/18731217902/count/ HTTP/1.1" 200 34
INFO 2018-12-09 11:59:17,604 basehttp 124 "GET /mobiles/18731217902/count/ HTTP/1.1" 200 34
INFO 2018-12-09 11:59:18,006 basehttp 124 "GET /mobiles/18731217902/count/ HTTP/1.1" 200 34
INFO 2018-12-09 11:59:18,361 basehttp 124 "GET /mobiles/18731217902/count/ HTTP/1.1" 200 34
INFO 2018-12-09 11:59:18,370 basehttp 124 "GET /mobiles/18731217902/count/ HTTP/1.1" 200 34
INFO 2018-12-09 11:59:35,810 basehttp 124 "GET /mobiles/18731217902/count/ HTTP/1.1" 200 34
INFO 2018-12-09 11:59:35,964 basehttp 124 "GET /mobiles/18731217902/count/ HTTP/1.1" 200 34
INFO 2018-12-09 11:59:36,102 basehttp 124 "GET /mobiles/18731217902/count/ HTTP/1.1" 200 34
INFO 2018-12-09 11:59:36,559 basehttp 124 "GET /mobiles/18731217902/count/ HTTP/1.1" 200 34
INFO 2018-12-09 11:59:36,838 basehttp 124 "GET /mobiles/18731217902/count/ HTTP/1.1" 200 34
INFO 2018-12-09 11:59:37,058 basehttp 124 "GET /mobiles/18731217902/count/ HTTP/1.1" 200 34
INFO 2018-12-09 11:59:37,863 basehttp 124 "GET /mobiles/18731217902/count/ HTTP/1.1" 200 34
INFO 2018-12-09 11:59:37,945 basehttp 124 "GET /mobiles/18731217902/count/ HTTP/1.1" 200 34
INFO 2018-12-09 11:59:38,382 basehttp 124 "GET /mobiles/18731217902/count/ HTTP/1.1" 200 34
INFO 2018-12-09 11:59:38,583 basehttp 124 "GET /mobiles/18731217902/count/ HTTP/1.1" 200 34
INFO 2018-12-09 11:59:38,680 basehttp 124 "GET /mobiles/18731217902/count/ HTTP/1.1" 200 34
INFO 2018-12-09 11:59:44,608 basehttp 124 "GET /mobiles/18731217902/count/ HTTP/1.1" 200 34
INFO 2018-12-09 11:59:44,781 basehttp 124 "GET /mobiles/18731217902/count/ HTTP/1.1" 200 34
INFO 2018-12-09 11:59:44,962 basehttp 124 "GET /mobiles/18731217902/count/ HTTP/1.1" 200 34
INFO 2018-12-09 11:59:56,900 basehttp 124 "GET /mobiles/18731217902/count/ HTTP/1.1" 200 34
INFO 2018-12-09 11:59:56,935 basehttp 124 "GET /mobiles/18731217902/count/ HTTP/1.1" 200 34
INFO 2018-12-09 11:59:57,211 basehttp 124 "GET /mobiles/18731217902/count/ HTTP/1.1" 200 34
INFO 2018-12-09 11:59:57,280 basehttp 124 "GET /mobiles/18731217902/count/ HTTP/1.1" 200 34
INFO 2018-12-09 11:59:57,427 basehttp 124 "GET /mobiles/18731217902/count/ HTTP/1.1" 200 34
INFO 2018-12-09 11:59:57,876 basehttp 124 "GET /mobiles/18731217902/count/ HTTP/1.1" 200 34
INFO 2018-12-09 11:59:57,987 basehttp 124 "GET /mobiles/18731217902/count/ HTTP/1.1" 200 34
INFO 2018-12-09 11:59:58,258 basehttp 124 "GET /mobiles/18731217902/count/ HTTP/1.1" 200 34
INFO 2018-12-09 12:00:02,428 basehttp 124 "GET /mobiles/18731217902/count/ HTTP/1.1" 200 34
INFO 2018-12-09 12:00:02,654 basehttp 124 "GET /mobiles/18731217902/count/ HTTP/1.1" 200 34
INFO 2018-12-09 12:00:02,775 basehttp 124 "GET /mobiles/18731217902/count/ HTTP/1.1" 200 34
INFO 2018-12-09 12:00:03,200 basehttp 124 "GET /mobiles/18731217902/count/ HTTP/1.1" 200 34
INFO 2018-12-09 12:00:03,236 basehttp 124 "GET /mobiles/18731217902/count/ HTTP/1.1" 200 34
INFO 2018-12-09 12:00:03,333 basehttp 124 "GET /mobiles/18731217902/count/ HTTP/1.1" 200 34
INFO 2018-12-09 12:00:03,532 basehttp 124 "GET /mobiles/18731217902/count/ HTTP/1.1" 200 34
INFO 2018-12-09 12:00:03,728 basehttp 124 "GET /mobiles/18731217902/count/ HTTP/1.1" 200 34
INFO 2018-12-09 12:00:03,930 basehttp 124 "GET /mobiles/18731217902/count/ HTTP/1.1" 200 34
INFO 2018-12-09 12:00:19,814 basehttp 124 "GET /mobiles/18731217902/count/ HTTP/1.1" 200 34
INFO 2018-12-09 12:43:54,081 basehttp 124 "GET /usernames/py234/count/ HTTP/1.1" 200 30
INFO 2018-12-09 12:44:21,388 basehttp 124 "GET /mobiles/13199999999/count/ HTTP/1.1" 200 34
INFO 2018-12-09 12:44:22,546 basehttp 124 "GET /mobiles/13199999999/count/ HTTP/1.1" 200 34
INFO 2018-12-09 12:44:23,169 basehttp 124 "GET /sms_code/13199999999/ HTTP/1.1" 200 16
INFO 2018-12-09 12:45:00,415 basehttp 124 "GET /mobiles/13199999999/count/ HTTP/1.1" 200 34
INFO 2018-12-09 12:45:00,460 basehttp 124 "GET /usernames/py234/count/ HTTP/1.1" 200 30
INFO 2018-12-09 12:45:07,829 basehttp 124 "GET /usernames/py234/count/ HTTP/1.1" 200 30
INFO 2018-12-09 12:45:07,841 basehttp 124 "GET /mobiles/13199999999/count/ HTTP/1.1" 200 34
INFO 2018-12-09 14:45:17,662 basehttp 124 "GET /oauth/qq/authorization/?next=/ HTTP/1.1" 200 195
INFO 2018-12-09 14:45:18,356 basehttp 124 "GET /oauth/qq/authorization/?next=/ HTTP/1.1" 200 195
INFO 2018-12-09 14:45:44,980 basehttp 124 "GET /oauth/qq/user/?code=F926E125C9C4676F454DE00D4230E256 HTTP/1.1" 200 234
INFO 2018-12-09 14:45:56,333 basehttp 124 "OPTIONS /user/ HTTP/1.1" 200 0
INFO 2018-12-09 14:45:56,974 basehttp 124 "GET /user/ HTTP/1.1" 200 88
INFO 2018-12-09 14:45:57,036 basehttp 124 "OPTIONS /browse_histories/ HTTP/1.1" 200 0
WARNING 2018-12-09 14:45:57,219 base 152 Not Found: /browse_histories/
WARNING 2018-12-09 14:45:57,228 basehttp 124 "GET /browse_histories/ HTTP/1.1" 404 3145
INFO 2018-12-10 09:10:24,418 basehttp 124 "OPTIONS /user/ HTTP/1.1" 200 0
INFO 2018-12-10 09:10:27,038 basehttp 124 "GET /user/ HTTP/1.1" 200 88
INFO 2018-12-10 09:10:27,078 basehttp 124 "OPTIONS /browse_histories/ HTTP/1.1" 200 0
WARNING 2018-12-10 09:10:27,490 base 152 Not Found: /browse_histories/
WARNING 2018-12-10 09:10:27,496 basehttp 124 "GET /browse_histories/ HTTP/1.1" 404 3301
INFO 2018-12-10 09:10:57,965 basehttp 124 "OPTIONS /emails/ HTTP/1.1" 200 0
WARNING 2018-12-10 09:10:57,977 base 152 Not Found: /emails/
WARNING 2018-12-10 09:10:57,978 basehttp 124 "PUT /emails/ HTTP/1.1" 404 3271
INFO 2018-12-10 09:12:13,447 basehttp 124 "OPTIONS /user/ HTTP/1.1" 200 0
INFO 2018-12-10 09:12:13,964 basehttp 124 "GET /user/ HTTP/1.1" 200 88
INFO 2018-12-10 09:12:14,010 basehttp 124 "OPTIONS /browse_histories/ HTTP/1.1" 200 0
WARNING 2018-12-10 09:12:14,042 base 152 Not Found: /browse_histories/
WARNING 2018-12-10 09:12:14,051 basehttp 124 "GET /browse_histories/ HTTP/1.1" 404 3302
INFO 2018-12-10 09:12:28,232 basehttp 124 "OPTIONS /emails/ HTTP/1.1" 200 0
INFO 2018-12-10 09:12:28,688 basehttp 124 "PUT /emails/ HTTP/1.1" 200 30
INFO 2018-12-10 09:16:05,006 basehttp 124 "GET /user/ HTTP/1.1" 200 88
WARNING 2018-12-10 09:16:05,091 base 152 Not Found: /browse_histories/
WARNING 2018-12-10 09:16:05,099 basehttp 124 "GET /browse_histories/ HTTP/1.1" 404 3302
INFO 2018-12-10 09:46:58,298 basehttp 124 "OPTIONS /user/ HTTP/1.1" 200 0
INFO 2018-12-10 09:46:59,126 basehttp 124 "GET /user/ HTTP/1.1" 200 88
INFO 2018-12-10 09:46:59,143 basehttp 124 "OPTIONS /browse_histories/ HTTP/1.1" 200 0
WARNING 2018-12-10 09:46:59,185 base 152 Not Found: /browse_histories/
WARNING 2018-12-10 09:46:59,190 basehttp 124 "GET /browse_histories/ HTTP/1.1" 404 3302
INFO 2018-12-10 09:47:10,916 basehttp 124 "OPTIONS /emails/ HTTP/1.1" 200 0
INFO 2018-12-10 09:47:11,578 basehttp 124 "PUT /emails/ HTTP/1.1" 200 35
INFO 2018-12-10 09:53:49,308 basehttp 124 "GET /user/ HTTP/1.1" 200 88
WARNING 2018-12-10 09:53:49,350 base 152 Not Found: /browse_histories/
WARNING 2018-12-10 09:53:49,358 basehttp 124 "GET /browse_histories/ HTTP/1.1" 404 3302
INFO 2018-12-10 09:54:09,137 basehttp 124 "PUT /emails/ HTTP/1.1" 200 35
INFO 2018-12-10 10:23:53,697 basehttp 124 "OPTIONS /user/ HTTP/1.1" 200 0
INFO 2018-12-10 10:23:53,981 basehttp 124 "GET /user/ HTTP/1.1" 200 88
INFO 2018-12-10 10:23:53,995 basehttp 124 "OPTIONS /browse_histories/ HTTP/1.1" 200 0
WARNING 2018-12-10 10:23:54,036 base 152 Not Found: /browse_histories/
WARNING 2018-12-10 10:23:54,046 basehttp 124 "GET /browse_histories/ HTTP/1.1" 404 3302
INFO 2018-12-10 10:24:07,060 basehttp 124 "OPTIONS /emails/ HTTP/1.1" 200 0
INFO 2018-12-10 10:24:07,282 basehttp 124 "PUT /emails/ HTTP/1.1" 200 35
INFO 2018-12-10 10:27:18,897 basehttp 124 "GET /user/ HTTP/1.1" 200 88
WARNING 2018-12-10 10:27:18,965 base 152 Not Found: /browse_histories/
WARNING 2018-12-10 10:27:18,977 basehttp 124 "GET /browse_histories/ HTTP/1.1" 404 3302
INFO 2018-12-10 10:27:28,178 basehttp 124 "PUT /emails/ HTTP/1.1" 200 35
INFO 2018-12-10 10:33:50,755 basehttp 124 "GET /user/ HTTP/1.1" 200 88
WARNING 2018-12-10 10:33:50,779 base 152 Not Found: /browse_histories/
WARNING 2018-12-10 10:33:50,786 basehttp 124 "GET /browse_histories/ HTTP/1.1" 404 3302
INFO 2018-12-10 10:33:59,658 basehttp 124 "PUT /emails/ HTTP/1.1" 200 35
INFO 2018-12-10 10:40:06,912 basehttp 124 "OPTIONS /authorizations/ HTTP/1.1" 200 0
INFO 2018-12-10 10:40:07,146 basehttp 124 "POST /authorizations/ HTTP/1.1" 200 230
INFO 2018-12-10 10:40:13,131 basehttp 124 "OPTIONS /user/ HTTP/1.1" 200 0
INFO 2018-12-10 10:40:13,328 basehttp 124 "GET /user/ HTTP/1.1" 200 86
INFO 2018-12-10 10:40:13,333 basehttp 124 "OPTIONS /browse_histories/ HTTP/1.1" 200 0
WARNING 2018-12-10 10:40:13,362 base 152 Not Found: /browse_histories/
WARNING 2018-12-10 10:40:13,373 basehttp 124 "GET /browse_histories/ HTTP/1.1" 404 3302
INFO 2018-12-10 10:40:24,103 basehttp 124 "OPTIONS /emails/ HTTP/1.1" 200 0
INFO 2018-12-10 10:40:24,201 basehttp 124 "PUT /emails/ HTTP/1.1" 200 36
INFO 2018-12-10 10:46:37,738 basehttp 124 "POST /authorizations/ HTTP/1.1" 200 230
INFO 2018-12-10 10:46:41,929 basehttp 124 "GET /user/ HTTP/1.1" 200 86
WARNING 2018-12-10 10:46:41,995 base 152 Not Found: /browse_histories/
WARNING 2018-12-10 10:46:41,998 basehttp 124 "GET /browse_histories/ HTTP/1.1" 404 3302
INFO 2018-12-10 10:46:51,315 basehttp 124 "PUT /emails/ HTTP/1.1" 200 35
INFO 2018-12-10 10:51:03,104 basehttp 124 "OPTIONS /user/ HTTP/1.1" 200 0
INFO 2018-12-10 10:51:03,446 basehttp 124 "GET /user/ HTTP/1.1" 200 86
INFO 2018-12-10 10:51:03,467 basehttp 124 "OPTIONS /browse_histories/ HTTP/1.1" 200 0
WARNING 2018-12-10 10:51:03,490 base 152 Not Found: /browse_histories/
WARNING 2018-12-10 10:51:03,498 basehttp 124 "GET /browse_histories/ HTTP/1.1" 404 3302
INFO 2018-12-10 10:51:11,275 basehttp 124 "OPTIONS /emails/ HTTP/1.1" 200 0
INFO 2018-12-10 10:51:11,511 basehttp 124 "PUT /emails/ HTTP/1.1" 200 35
INFO 2018-12-10 10:51:39,807 basehttp 124 "OPTIONS /authorizations/ HTTP/1.1" 200 0
INFO 2018-12-10 10:51:39,946 basehttp 124 "POST /authorizations/ HTTP/1.1" 200 230
INFO 2018-12-10 10:53:11,763 basehttp 124 "GET /user/ HTTP/1.1" 200 86
WARNING 2018-12-10 10:53:11,791 base 152 Not Found: /browse_histories/
WARNING 2018-12-10 10:53:11,795 basehttp 124 "GET /browse_histories/ HTTP/1.1" 404 3302
INFO 2018-12-10 10:53:25,389 basehttp 124 "PUT /emails/ HTTP/1.1" 200 36
INFO 2018-12-10 10:55:22,932 basehttp 124 "GET /oauth/qq/authorization/?next=/ HTTP/1.1" 200 195
INFO 2018-12-10 10:55:36,601 basehttp 124 "GET /oauth/qq/user/?code=618C98EAB85C8C57A97F4CDD184BFDC9 HTTP/1.1" 200 234
INFO 2018-12-10 10:55:41,352 basehttp 124 "GET /user/ HTTP/1.1" 200 88
WARNING 2018-12-10 10:55:41,417 base 152 Not Found: /browse_histories/
WARNING 2018-12-10 10:55:41,421 basehttp 124 "GET /browse_histories/ HTTP/1.1" 404 3302
INFO 2018-12-10 10:55:49,547 basehttp 124 "PUT /emails/ HTTP/1.1" 200 35
INFO 2018-12-10 11:00:55,363 basehttp 124 "GET /user/ HTTP/1.1" 200 88
WARNING 2018-12-10 11:00:55,390 base 152 Not Found: /browse_histories/
WARNING 2018-12-10 11:00:55,392 basehttp 124 "GET /browse_histories/ HTTP/1.1" 404 3302
INFO 2018-12-10 11:01:06,844 basehttp 124 "PUT /emails/ HTTP/1.1" 200 33
INFO 2018-12-10 11:04:29,884 basehttp 124 "OPTIONS /authorizations/ HTTP/1.1" 200 0
INFO 2018-12-10 11:04:30,148 basehttp 124 "POST /authorizations/ HTTP/1.1" 200 230
INFO 2018-12-10 11:04:34,077 basehttp 124 "OPTIONS /user/ HTTP/1.1" 200 0
INFO 2018-12-10 11:04:34,200 basehttp 124 "GET /user/ HTTP/1.1" 200 86
INFO 2018-12-10 11:04:34,213 basehttp 124 "OPTIONS /browse_histories/ HTTP/1.1" 200 0
WARNING 2018-12-10 11:04:34,243 base 152 Not Found: /browse_histories/
WARNING 2018-12-10 11:04:34,252 basehttp 124 "GET /browse_histories/ HTTP/1.1" 404 3302
INFO 2018-12-10 11:04:48,470 basehttp 124 "OPTIONS /emails/ HTTP/1.1" 200 0
INFO 2018-12-10 11:04:48,770 basehttp 124 "PUT /emails/ HTTP/1.1" 200 33
